Workbook
Name _Ref171496331: Display!$AR$11

Sheet Raw
A1: Flows | B1: M | C1: EoL | D1: E | E1: R1 | F1: R2 | G1: C1 | H1: C2 | I1: F1 | J1: F2 | K1: F3 | L1: F4 | M1: SC1 | N1: SC2 | O1: SC3 | P1: P1 | Q1: P2 | R1: P3 | S1: P4 | T1: P5 | U1: P6 | V1: P7 | W1: P8 | X1: Use | Y1: Semi | Z1: Offset | AA1: W | AB1: Sink | AC1: Total outflow | AD1: Efficiency | AE1: Value | AF1: Scrap/Loss | AG1: R1_ratio | AH1: R2_ratio | AI1: Export_ratio
A2: M | B2: 0 | C2: 0 | D2: =upstream!E2 -> 385.41176 | E2: 0 | F2: 0 | G2: 0 | H2: 0 | I2: 0 | J2: 0 | K2: 0 | L2: 0 | M2: 0 | N2: 0 | O2: 0 | P2: 0 | Q2: 0 | R2: 0 | S2: 0 | T2: 0 | U2: 0 | V2: 0 | W2: 0 | X2: 0 | Y2: 0 | Z2: =upstream!E3 -> 302.82353 | AA2: =upstream!E4 -> 37.814706 | AB2: =SUM(X2:AA2) -> 340.63824 | AC2: =SUM(B2:AA2) -> 726.05 | AD2: =AE2/AC2 -> 0.94791722 | AE2: =SUM(B2:Z2) -> 688.23529
A3: EoL | B3: 0 | C3: 0 | D3: 0 | E3: =upstream!W7 -> 2220.931 | F3: =upstream!W8 -> 1638.0024 | G3: 0 | H3: 0 | I3: 0 | J3: 0 | K3: 0 | L3: 0 | M3: 0 | N3: 0 | O3: 0 | P3: 0 | Q3: 0 | R3: 0 | S3: 0 | T3: 0 | U3: 0 | V3: 0 | W3: 0 | X3: 0 | Y3: 0 | Z3: =upstream!M3 -> 1894.6816 | AA3: 0 | AB3: =SUM(X3:AA3) -> 1894.6816 | AC3: =SUM(B3:AA3) -> 5753.615 | AD3: =AE3/AC3 -> 1 | AE3: =SUM(B3:Z3) -> 5753.615
A4: E | B4: 0 | C4: 0 | D4: 0 | E4: =upstream!H8 -> 31.353004 | F4: =upstream!I8 -> 31.353004 | G4: =upstream!F8 -> 715.80655 | H4: =upstream!G8 -> 231.48744 | I4: 0 | J4: 0 | K4: 0 | L4: 0 | M4: 0 | N4: 0 | O4: 0 | P4: 0 | Q4: 0 | R4: 0 | S4: 0 | T4: 0 | U4: 0 | V4: 0 | W4: 0 | X4: 0 | Y4: 0 | Z4: 0 | AA4: =upstream!E9 -> 15.031176 | AB4: =SUM(X4:AA4) -> 15.031176 | AC4: =SUM(B4:AA4) -> 1025.0312 | AD4: =AE4/AC4 -> 0.98533588 | AE4: =SUM(B4:Z4) -> 1010
A5: R1 | B5: 0 | C5: 0 | D5: 0 | E5: 0 | F5: 0 | G5: =upstream!N17 -> 6472.1049 | H5: 0 | I5: 0 | J5: 0 | K5: 0 | L5: 0 | M5: 0 | N5: 0 | O5: 0 | P5: 0 | Q5: 0 | R5: 0 | S5: 0 | T5: 0 | U5: 0 | V5: 0 | W5: 0 | X5: 0 | Y5: 0 | Z5: 0 | AA5: =upstream!W20 -> 340.6371 | AB5: =SUM(X5:AA5) -> 340.6371 | AC5: =SUM(B5:AA5) -> 6812.742 | AD5: =AE5/AC5 -> 0.95 | AE5: =SUM(B5:Z5) -> 6472.1049
A6: R2 | B6: 0 | C6: 0 | D6: 0 | E6: 0 | F6: 0 | G6: 0 | H6: =upstream!N26 -> 1995.482 | I6: 0 | J6: 0 | K6: 0 | L6: 0 | M6: 0 | N6: 0 | O6: 0 | P6: 0 | Q6: 0 | R6: 0 | S6: 0 | T6: 0 | U6: 0 | V6: 0 | W6: 0 | X6: 0 | Y6: 0 | Z6: 0 | AA6: =upstream!W32 -> 105.02537 | AB6: =SUM(X6:AA6) -> 105.02537 | AC6: =SUM(B6:AA6) -> 2100.5074 | AD6: =AE6/AC6 -> 0.95 | AE6: =SUM(B6:Z6) -> 1995.482
A7: C1 | B7: 0 | C7: 0 | D7: 0 | E7: 0 | F7: 0 | G7: 0 | H7: 0 | I7: =upstream!E13 -> 4834.8536 | J7: =upstream!E14 -> 1916.96 | K7: =upstream!E15 -> 378.41423 | L7: =upstream!E16 -> 131.72096 | M7: 0 | N7: 0 | O7: 0 | P7: 0 | Q7: 0 | R7: 0 | S7: 0 | T7: 0 | U7: 0 | V7: 0 | W7: 0 | X7: 0 | Y7: 0 | Z7: =upstream!H17 -> 91.691272 | AA7: 0 | AB7: =SUM(X7:AA7) -> 91.691272 | AC7: =SUM(B7:AA7) -> 7353.64 | AD7: 1 | AE7: =SUM(B7:Z7) -> 7353.64
A8: C2 | B8: 0 | C8: 0 | D8: 0 | E8: 0 | F8: 0 | G8: 0 | H8: 0 | I8: 0 | J8: 0 | K8: 0 | L8: 0 | M8: =upstream!E23 -> 1083.8643 | N8: =upstream!E24 -> 743.34429 | O8: =upstream!E25 -> 340.04771 | P8: 0 | Q8: 0 | R8: 0 | S8: 0 | T8: 0 | U8: 0 | V8: 0 | W8: 0 | X8: 0 | Y8: 0 | Z8: =upstream!H26 -> 113.30873 | AA8: 0 | AB8: =SUM(X8:AA8) -> 113.30873 | AC8: =SUM(B8:AA8) -> 2280.5651 | AD8: 1 | AE8: =SUM(M8:Z8) -> 2280.5651
A9: F1 | B9: 0 | C9: 0 | D9: 0 | E9: =AF9*AG9 -> 1496.4611 | F9: =AF9*AH9 -> 166.27346 | G9: 0 | H9: 0 | I9: 0 | J9: 0 | K9: 0 | L9: 0 | M9: 0 | N9: 0 | O9: 0 | P9: =P32*0.453592*P$41*P$43 -> 434.83429 | Q9: =Q32*0.453592*Q$41*Q$43 -> 629.22666 | R9: =R32*0.453592*R$41*R$43 -> 412.68833 | S9: =S32*0.453592*S$41*S$43 -> 266.80617 | T9: =T32*0.453592*T$41*T$43 -> 117.7603 | U9: =U32*0.453592*U$41*U$43 -> 200.36827 | V9: =V32*0.453592*V$41*V$43 -> 1745.6646 | W9: =W32*0.453592*W$41*W$43 -> 22.849013 | X9: 0 | Y9: =Y32*$Y$41*$Y$43*0.453592 -> 195.13086 | Z9: 0 | AA9: 0 | AB9: =SUM(X9:AA9) -> 195.13086 | AC9: =AE9/AD9 -> 5688.0631 | AD9: 0.70768 | AE9: =SUM(P9:Y9) -> 4025.3285 | AF9: =AC9-AE9 -> 1662.7346 | AG9: =$AG$25*$AG$27 -> 0.9 | AH9: =1-AG9-AI9 -> 0.1 | AI9: =1-$AG$27 -> 0 | AJ9: =SUM(AG9:AI9) -> 1
A10: F2 | B10: 0 | C10: 0 | D10: 0 | E10: =AF10*AG10 -> 563.83784 | F10: =AF10*AH10 -> 62.648649 | G10: 0 | H10: 0 | I10: 0 | J10: 0 | K10: 0 | L10: 0 | M10: 0 | N10: 0 | O10: 0 | P10: =P33*0.453592*P$41*P$43 -> 662.26985 | Q10: =Q33*0.453592*Q$41*Q$43 -> 178.57382 | R10: =R33*0.453592*R$41*R$43 -> 297.38869 | S10: =S33*0.453592*S$41*S$43 -> 165.56746 | T10: =T33*0.453592*T$41*T$43 -> 165.21594 | U10: =U33*0.453592*U$41*U$43 -> 164.86442 | V10: =V33*0.453592*V$41*V$43 -> 0 | W10: =W33*0.453592*W$41*W$43 -> 27.770339 | X10: 0 | Y10: =Y33*$Y$41*$Y$43*0.453592 -> 108.06298 | Z10: 0 | AA10: 0 | AB10: =SUM(X10:AA10) -> 108.06298 | AC10: =AE10/AD10 -> 2396.2 | AD10: 0.73855 | AE10: =SUM(P10:Y10) -> 1769.7135 | AF10: =AC10-AE10 -> 626.48649 | AG10: =$AG$25*$AG$27 -> 0.9 | AH10: =1-AG10-AI10 -> 0.1 | AI10: =1-$AG$27 -> 0 | AJ10: =SUM(AG10:AI10) -> 1
A11: F3 | B11: 0 | C11: 0 | D11: 0 | E11: =AF11*AG11 -> 111.30345 | F11: =AF11*AH11 -> 12.36705 | G11: 0 | H11: 0 | I11: 0 | J11: 0 | K11: 0 | L11: 0 | M11: 0 | N11: 0 | O11: 0 | P11: =P34*0.453592*P$41*P$43 -> 9.8426517 | Q11: =Q34*0.453592*Q$41*Q$43 -> 1.4060931 | R11: =R34*0.453592*R$41*R$43 -> 4.9213259 | S11: =S34*0.453592*S$41*S$43 -> 1.7576164 | T11: =T34*0.453592*T$41*T$43 -> 318.83161 | U11: =U34*0.453592*U$41*U$43 -> 4.9213259 | V11: =V34*0.453592*V$41*V$43 -> 0.35152328 | W11: =W34*0.453592*W$41*W$43 -> 1.7576164 | X11: 0 | Y11: =Y34*$Y$41*$Y$43*0.453592 -> 5.5575244 | Z11: 0 | AA11: 0 | AB11: =SUM(X11:AA11) -> 5.5575244 | AC11: =AE11/AD11 -> 473.01779 | AD11: =AD10 -> 0.73855 | AE11: =SUM(P11:Y11) -> 349.34729 | AF11: =AC11-AE11 -> 123.6705 | AG11: =$AG$25*$AG$27 -> 0.9 | AH11: =1-AG11-AI11 -> 0.1 | AI11: =1-$AG$27 -> 0 | AJ11: =SUM(AG11:AI11) -> 1
A12: F4 | B12: 0 | C12: 0 | D12: 0 | E12: =AF12*AG12 -> 29.637215 | F12: =AF12*AH12 -> 3.2930239 | G12: 0 | H12: 0 | I12: 0 | J12: 0 | K12: 0 | L12: 0 | M12: 0 | N12: 0 | O12: 0 | P12: =P35*0.453592*P$41*P$43 -> 0 | Q12: =Q35*0.453592*Q$41*Q$43 -> 25.661199 | R12: =R35*0.453592*R$41*R$43 -> 49.564782 | S12: =S35*0.453592*S$41*S$43 -> 6.327419 | T12: =T35*0.453592*T$41*T$43 -> 0.35152328 | U12: =U35*0.453592*U$41*U$43 -> 3.5152328 | V12: =V35*0.453592*V$41*V$43 -> 0 | W12: =W35*0.453592*W$41*W$43 -> 37.964514 | X12: 0 | Y12: =Y35*$Y$41*$Y$43*0.453592 -> 8.3362866 | Z12: 0 | AA12: 0 | AB12: =SUM(X12:AA12) -> 8.3362866 | AC12: =AE12/AD12 -> 164.6512 | AD12: 0.8 | AE12: =SUM(P12:Y12) -> 131.72096 | AF12: =AC12-AE12 -> 32.930239 | AG12: =$AG$25*$AG$27 -> 0.9 | AH12: =1-AG12-AI12 -> 0.1 | AI12: =1-$AG$27 -> 0 | AJ12: =SUM(AG12:AI12) -> 1
A13: SC1 | B13: 0 | C13: 0 | D13: 0 | E13: 0 | F13: 0 | G13: 0 | H13: 0 | I13: 0 | J13: 0 | K13: 0 | L13: 0 | M13: 0 | N13: 0 | O13: 0 | P13: =P36*0.453592*P$41*P$43 -> 12.654838 | Q13: =Q36*0.453592*Q$41*Q$43 -> 388.29261 | R13: =R36*0.453592*R$41*R$43 -> 86.900254 | S13: =S36*0.453592*S$41*S$43 -> 72.765318 | T13: =T36*0.453592*T$41*T$43 -> 46.190158 | U13: =U36*0.453592*U$41*U$43 -> 126.12655 | V13: =V36*0.453592*V$41*V$43 -> 0 | W13: =W36*0.453592*W$41*W$43 -> 90.693005 | X13: 0 | Y13: =Y36*$Y$41*$Y$43*0.453592 -> 268.05459 | Z13: 0 | AA13: =0.2*(1-AD13)/AD13*AE13 -> 49.232507 | AB13: =SUM(X13:AA13) -> 317.28709 | AC13: =SUM(B13:AA13) -> 1140.9098 | AD13: =0.816 -> 0.816 | AE13: =SUM(P13:Y13) -> 1091.6773 | AF13: =AC13-AE13 -> 49.232507 | AG13: 0 | AH13: 0 | AI13: =1-$AG$27 -> 0 | AJ13: =SUM(AG13:AI13) -> 0
A14: SC2 | B14: 0 | C14: 0 | D14: 0 | E14: 0 | F14: 0 | G14: 0 | H14: 0 | I14: 0 | J14: 0 | K14: 0 | L14: 0 | M14: 0 | N14: 0 | O14: 0 | P14: =P37*0.453592*P$41*P$43 -> 0 | Q14: =Q37*0.453592*Q$41*Q$43 -> 357.47574 | R14: =R37*0.453592*R$41*R$43 -> 39.500115 | S14: =S37*0.453592*S$41*S$43 -> 36.382659 | T14: =T37*0.453592*T$41*T$43 -> 23.095079 | U14: =U37*0.453592*U$41*U$43 -> 63.063276 | V14: =V37*0.453592*V$41*V$43 -> 0 | W14: =W37*0.453592*W$41*W$43 -> 45.346503 | X14: 0 | Y14: =Y37*$Y$41*$Y$43*0.453592 -> 183.83929 | Z14: 0 | AA14: =0.2*(1-AD14)/AD14*AE14 -> 33.765022 | AB14: =SUM(X14:AA14) -> 217.60431 | AC14: =SUM(B14:AA14) -> 782.46768 | AD14: =AD13 -> 0.816 | AE14: =SUM(P14:Y14) -> 748.70265 | AF14: =AC14-AE14 -> 33.765022 | AG14: 0 | AH14: 0 | AI14: =1-$AG$27 -> 0 | AJ14: =SUM(AG14:AI14) -> 0
A15: SC3 | B15: 0 | C15: 0 | D15: 0 | E15: 0 | F15: 0 | G15: 0 | H15: 0 | I15: 0 | J15: 0 | K15: 0 | L15: 0 | M15: 0 | N15: 0 | O15: 0 | P15: =P38*0.453592*P$41*P$43 -> 0 | Q15: =Q38*0.453592*Q$41*Q$43 -> 178.73787 | R15: =R38*0.453592*R$41*R$43 -> 23.700069 | S15: =S38*0.453592*S$41*S$43 -> 12.127553 | T15: =T38*0.453592*T$41*T$43 -> 7.6983597 | U15: =U38*0.453592*U$41*U$43 -> 21.021092 | V15: =V38*0.453592*V$41*V$43 -> 0 | W15: =W38*0.453592*W$41*W$43 -> 15.115501 | X15: 0 | Y15: =Y38*$Y$41*$Y$43*0.453592 -> 84.098484 | Z15: 0 | AA15: =0.2*(1-AD15)/AD15*AE15 -> 15.44603 | AB15: =SUM(X15:AA15) -> 99.544514 | AC15: =SUM(B15:AA15) -> 357.94496 | AD15: =AD13 -> 0.816 | AE15: =SUM(P15:Y15) -> 342.49893 | AF15: =AC15-AE15 -> 15.44603 | AG15: 0 | AH15: 0 | AI15: =1-$AG$27 -> 0 | AJ15: =SUM(AG15:AI15) -> 0
A16: P1 | B16: 0 | C16: 0 | D16: 0 | E16: =AF16*AG16 -> 108.91113 | F16: =AF16*AH16 -> 12.101236 | G16: 0 | H16: 0 | I16: 0 | J16: 0 | K16: 0 | L16: 0 | M16: 0 | N16: 0 | O16: 0 | P16: 0 | Q16: 0 | R16: 0 | S16: 0 | T16: 0 | U16: 0 | V16: 0 | W16: 0 | X16: =end_use!M2 -> 1173.238 | Y16: 0 | Z16: 0 | AA16: 0 | AB16: =SUM(X16:AA16) -> 1173.238 | AC16: {=TRANSPOSE(P42:W42)} -> 1294.2504 | AD16: =end_use!Q2 -> 0.90650004 | AE16: =SUM(P16:Y16) -> 1173.238 | AF16: =AC16-AE16 -> 121.01236 | AG16: =$AG$26 -> 0.9 | AH16: =1-AG16-AI16 -> 0.1 | AI16: =1-$AG$28 -> 0 | AJ16: =SUM(AG16:AI16) -> 1
A17: P2 | B17: 0 | C17: 0 | D17: 0 | E17: =AF17*AG17 -> 230.04078 | F17: =AF17*AH17 -> 25.560087 | G17: 0 | H17: 0 | I17: 0 | J17: 0 | K17: 0 | L17: 0 | M17: 0 | N17: 0 | O17: 0 | P17: 0 | Q17: 0 | R17: 0 | S17: 0 | T17: 0 | U17: 0 | V17: 0 | W17: 0 | X17: =end_use!M3 -> 1778.2212 | Y17: 0 | Z17: 0 | AA17: 0 | AB17: =SUM(X17:AA17) -> 1778.2212 | AC17: 2033.822 | AD17: =end_use!Q3 -> 0.87432486 | AE17: =SUM(P17:Y17) -> 1778.2212 | AF17: =AC17-AE17 -> 255.60087 | AG17: =$AG$26 -> 0.9 | AH17: =1-AG17-AI17 -> 0.1 | AI17: =1-$AG$28 -> 0 | AJ17: =SUM(AG17:AI17) -> 1
A18: P3 | B18: 0 | C18: 0 | D18: 0 | E18: =AF18*AG18 -> 163.95462 | F18: =AF18*AH18 -> 18.21718 | G18: 0 | H18: 0 | I18: 0 | J18: 0 | K18: 0 | L18: 0 | M18: 0 | N18: 0 | O18: 0 | P18: 0 | Q18: 0 | R18: 0 | S18: 0 | T18: 0 | U18: 0 | V18: 0 | W18: 0 | X18: =end_use!M4 -> 875.17185 | Y18: 0 | Z18: 0 | AA18: 0 | AB18: =SUM(X18:AA18) -> 875.17185 | AC18: 1057.3436 | AD18: =end_use!Q4 -> 0.82770805 | AE18: =SUM(P18:Y18) -> 875.17185 | AF18: =AC18-AE18 -> 182.1718 | AG18: =$AG$26 -> 0.9 | AH18: =1-AG18-AI18 -> 0.1 | AI18: =1-$AG$28 -> 0 | AJ18: =SUM(AG18:AI18) -> 1
A19: P4 | B19: 0 | C19: 0 | D19: 0 | E19: =AF19*AG19 -> 67.033247 | F19: =AF19*AH19 -> 7.4481385 | G19: 0 | H19: 0 | I19: 0 | J19: 0 | K19: 0 | L19: 0 | M19: 0 | N19: 0 | O19: 0 | P19: 0 | Q19: 0 | R19: 0 | S19: 0 | T19: 0 | U19: 0 | V19: 0 | W19: 0 | X19: =end_use!M5 -> 574.87878 | Y19: 0 | Z19: 0 | AA19: 0 | AB19: =SUM(X19:AA19) -> 574.87878 | AC19: 649.36016 | AD19: =end_use!Q5 -> 0.88530035 | AE19: =SUM(P19:Y19) -> 574.87878 | AF19: =AC19-AE19 -> 74.481385 | AG19: =$AG$26 -> 0.9 | AH19: =1-AG19-AI19 -> 0.1 | AI19: =1-$AG$28 -> 0 | AJ19: =SUM(AG19:AI19) -> 1
A20: P5 | B20: 0 | C20: 0 | D20: 0 | E20: =AF20*AG20 -> 52.926092 | F20: =AF20*AH20 -> 5.8806768 | G20: 0 | H20: 0 | I20: 0 | J20: 0 | K20: 0 | L20: 0 | M20: 0 | N20: 0 | O20: 0 | P20: 0 | Q20: 0 | R20: 0 | S20: 0 | T20: 0 | U20: 0 | V20: 0 | W20: 0 | X20: =end_use!M6 -> 726.27698 | Y20: 0 | Z20: 0 | AA20: 0 | AB20: =SUM(X20:AA20) -> 726.27698 | AC20: 785.08375 | AD20: =end_use!Q6 -> 0.92509491 | AE20: =SUM(P20:Y20) -> 726.27698 | AF20: =AC20-AE20 -> 58.806768 | AG20: =$AG$26 -> 0.9 | AH20: =1-AG20-AI20 -> 0.1 | AI20: =1-$AG$28 -> 0 | AJ20: =SUM(AG20:AI20) -> 1
A21: P6 | B21: 0 | C21: 0 | D21: 0 | E21: =AF21*AG21 -> 56.901543 | F21: =AF21*AH21 -> 6.3223936 | G21: 0 | H21: 0 | I21: 0 | J21: 0 | K21: 0 | L21: 0 | M21: 0 | N21: 0 | O21: 0 | P21: 0 | Q21: 0 | R21: 0 | S21: 0 | T21: 0 | U21: 0 | V21: 0 | W21: 0 | X21: =end_use!M7 -> 611.73678 | Y21: 0 | Z21: 0 | AA21: 0 | AB21: =SUM(X21:AA21) -> 611.73678 | AC21: 674.96072 | AD21: =end_use!Q7 -> 0.90632946 | AE21: =SUM(P21:Y21) -> 611.73678 | AF21: =AC21-AE21 -> 63.223936 | AG21: =$AG$26 -> 0.9 | AH21: =1-AG21-AI21 -> 0.1 | AI21: =1-$AG$28 -> 0 | AJ21: =SUM(AG21:AI21) -> 1
A22: P7 | B22: 0 | C22: 0 | D22: 0 | E22: =AF22*AG22 -> 286.68991 | F22: =AF22*AH22 -> 31.854435 | G22: 0 | H22: 0 | I22: 0 | J22: 0 | K22: 0 | L22: 0 | M22: 0 | N22: 0 | O22: 0 | P22: 0 | Q22: 0 | R22: 0 | S22: 0 | T22: 0 | U22: 0 | V22: 0 | W22: 0 | X22: =end_use!M8 -> 1699.8361 | Y22: 0 | Z22: 0 | AA22: 0 | AB22: =SUM(X22:AA22) -> 1699.8361 | AC22: 2018.3804 | AD22: =end_use!Q8 -> 0.84217824 | AE22: =SUM(P22:Y22) -> 1699.8361 | AF22: =AC22-AE22 -> 318.54435 | AG22: =$AG$26 -> 0.9 | AH22: =1-AG22-AI22 -> 0.1 | AI22: =1-$AG$28 -> 0 | AJ22: =SUM(AG22:AI22) -> 1
A23: P8 | B23: 0 | C23: 0 | D23: 0 | E23: =AF23*AG23 -> 7.084001 | F23: =AF23*AH23 -> 0.78711122 | G23: 0 | H23: 0 | I23: 0 | J23: 0 | K23: 0 | L23: 0 | M23: 0 | N23: 0 | O23: 0 | P23: 0 | Q23: 0 | R23: 0 | S23: 0 | T23: 0 | U23: 0 | V23: 0 | W23: 0 | X23: =end_use!M9 -> 271.29687 | Y23: 0 | Z23: 0 | AA23: 0 | AB23: =SUM(X23:AA23) -> 271.29687 | AC23: 279.16798 | AD23: =end_use!Q9 -> 0.9718051 | AE23: =SUM(P23:Y23) -> 271.29687 | AF23: =AC23-AE23 -> 7.8711122 | AG23: =$AG$26 -> 0.9 | AH23: =1-AG23-AI23 -> 0.1 | AI23: =1-$AG$28 -> 0 | AJ23: =SUM(AG23:AI23) -> 1
A24: dom inflow | B24: =SUM(B2:B23) -> 0 | C24: =SUM(C2:C23) -> 0 | D24: =SUM(D2:D23) -> 385.41176 | E24: =SUM(E2:E23) -> 5427.0649 | F24: =SUM(F2:F23) -> 2022.1089 | G24: =SUM(G2:G23) -> 7187.9114 | H24: =SUM(H2:H23) -> 2226.9694 | I24: =SUM(I2:I23) -> 4834.8536 | ... AC24: =SUM(AC2:AC23) -> 45847.774
A25: total outflow | B25: {=TRANSPOSE(AC2:AC23)} -> 726.05 | C25: 5753.615 | D25: 1025.0312 | E25: 6812.742 | F25: 2100.5074 | G25: 7353.64 | H25: 2280.5651 | I25: 5688.0631 | J25: 2396.2 | K25: 473.01779 | L25: 164.6512 | M25: 1140.9098 | N25: 782.46768 | O25: 357.94496 | P25: 1294.2504 | Q25: 2033.822 | R25: 1057.3436 | S25: 649.36016 | T25: 785.08375 | U25: 674.96072 | V25: 2018.3804 | W25: 279.16798 | AG25: 0.9 | AH25: Forming Scrap No downgrade rate
A26: import_amt | B26: =B27 -> 726.05 | C26: =C27 -> 1369.2421 | D26: =D25-D24 -> 639.61941 | E26: =E25-E24 -> 1385.6771 | F26: =F25-F24 -> 78.398506 | G26: =G25-G24 -> 165.72861 | H26: =H25-H24 -> 53.595615 | I26: =I25-I24 -> 853.20946 | J26: =J25-J24 -> 479.24 | K26: =K25-K24 -> 94.603558 | ... W26: =W25-W24 -> 37.67149 | AC26: =(AC24-A!AC52)<0.00001 -> TRUE | AG26: =0.9 -> 0.9 | AH26: Fabrication Scrap No downgrade rate
B27: =upstream!C3 -> 726.05 | C27: =upstream!M4 -> 1369.2421 | D27: =upstream!C9 -> 639.61941 | E27: =upstream!W17 -> 1385.6771 | F27: =upstream!W29 -> 78.398506 | H27: Dom Alloy% | I27: =I7/I25 -> 0.85 | J27: =I27 -> 0.85 | K27: =I27 -> 0.85 | L27: =I27 -> 0.85 | M27: =M8/M25 -> 0.95 | N27: =N8/N25 -> 0.95 | O27: =O8/O25 -> 0.95 | W27: =SUM(P26:W26) -> 1186.46 | AG27: 1 | AH27: Forming_Scrap_dom_rate
AG28: 1 | AH28: Product_scrap_dom_rate
D30: EoL scrap | E30: =E3+F3 -> 3858.9334 | P30: Construction | Q30: Transportation_auto | R30: Transportation_other | S30: Durables | T30: Electrical | U30: Machinery | V30: Container | W30: Other
D31: Internal scrap | E31: =SUM(E9:E23)+SUM(F9:F23) -> 3527.5344 | O31: M lb | P31: P1 | Q31: P2 | R31: P3 | S31: P4 | T31: P5 | U31: P6 | V31: P7 | W31: P8 | X31: Received | Y31: Export
N32: Sheet and Foil | O32: F1 | P32: =downstream!B3+downstream!B4 -> 1237 | Q32: =downstream!C3+downstream!C4 -> 1790 | R32: =downstream!D3+downstream!D4 -> 1174 | S32: =downstream!E3+downstream!E4 -> 759 | T32: =downstream!F3+downstream!F4 -> 335 | U32: =downstream!G3+downstream!G4 -> 570 | V32: =downstream!H3+downstream!H4 -> 4966 | W32: =downstream!I3+downstream!I4 -> 65 | X32: =SUM(P32:W32) -> 10896 | Y32: =downstream!K3+downstream!K4 -> 632
N33: Extrusions | O33: F2 | P33: =downstream!B5 -> 1884 | Q33: =downstream!C5 -> 508 | R33: =downstream!D5 -> 846 | S33: =downstream!E5 -> 471 | T33: =downstream!F5 -> 470 | U33: =downstream!G5 -> 469 | V33: =downstream!H5 -> 0 | W33: =downstream!I5 -> 79 | X33: =SUM(P33:W33) -> 4727 | Y33: =downstream!K5 -> 350
N34: Cable/Wire | O34: F3 | P34: =downstream!B6 -> 28 | Q34: =downstream!C6 -> 4 | R34: =downstream!D6 -> 14 | S34: =downstream!E6 -> 5 | T34: =downstream!F6 -> 907 | U34: =downstream!G6 -> 14 | V34: =downstream!H6 -> 1 | W34: =downstream!I6 -> 5 | X34: =SUM(P34:W34) -> 978 | Y34: =downstream!K6 -> 18
E35: Produced | F35: Import | G35: Export | H35: Consumed | I35: Verify Consumed | J35: dom_to_dom | N35: Forgings and Powder | O35: F4 | P35: =downstream!B7+downstream!B8 -> 0 | Q35: =downstream!C7+downstream!C8 -> 73 | R35: =downstream!D7+downstream!D8 -> 141 | S35: =downstream!E7+downstream!E8 -> 18 | T35: =downstream!F7+downstream!F8 -> 1 | U35: =downstream!G7+downstream!G8 -> 10 | V35: =downstream!H7+downstream!H8 -> 0 | W35: =downstream!I7+downstream!I8 -> 108 | X35: =SUM(P35:W35) -> 351 | Y35: =downstream!K7+downstream!K8 -> 27
D36: Metal | E36: =AE4 -> 1010 | F36: =E27+F27+G26+H26 -> 1683.3998 | G36: 0 | H36: =SUM(E4:H4)+SUM(E26:H26) -> 2693.3998 | I36: =E36+F36-G36 -> 2693.3998 | J36: =E36-G36 -> 1010 | M36: =SUM(P36:W36) -> 2343.0105 | N36: Die Casting | O36: SC1 | P36: =downstream!B$9*P47 -> 36 | Q36: =downstream!C$9*Q47 -> 1104.6 | R36: =downstream!D$9*R47 -> 247.21053 | S36: =downstream!E$9*S47 -> 207 | T36: =downstream!F$9*T47 -> 131.4 | U36: =downstream!G$9*U47 -> 358.8 | V36: =downstream!H$9*V47 -> 0 | W36: =downstream!I$9*W47 -> 258 | X36: =SUM(P36:W36) -> 2343.0105 | Y36: =downstream!K$9*L47 -> 868.18917
D37: Scrap | E37: =upstream!M2+E31 -> 7911.9073 | F37: =upstream!M4 -> 1369.2421 | G37: =upstream!M3 -> 1894.6816 | H37: =E3+F3+SUM(E9:E23)+SUM(F9:F23) -> 7386.4678 | I37: =E37+F37-G37 -> 7386.4678 | J37: =E37-G37 -> 6017.2257 | M37: =SUM(P37:W37) -> 1606.9018 | N37: Permanent Mold Castings | O37: SC2 | P37: =downstream!B$9*P48 -> 0 | Q37: =downstream!C$9*Q48 -> 1016.9333 | R37: =downstream!D$9*R48 -> 112.36842 | S37: =downstream!E$9*S48 -> 103.5 | T37: =downstream!F$9*T48 -> 65.7 | U37: =downstream!G$9*U48 -> 179.4 | V37: =downstream!H$9*V48 -> 0 | W37: =downstream!I$9*W48 -> 129 | X37: =SUM(P37:W37) -> 1606.9018 | Y37: =downstream!K$9*L48 -> 595.42827
D38: Alloy | E38: =AE7+AE8 -> 9634.2051 | F38: =SUM(I26:O26) -> 1574.0494 | G38: =Z7+Z8 -> 205 | H38: =SUM(AC9:AC15) -> 11003.254 | I38: =E38+F38-G38 -> 11003.254 | J38: =E38-G38 -> 9429.2051 | M38: =SUM(P38:W38) -> 735.08772 | N38: Sand Casting | O38: SC3 | P38: =downstream!B$9*P49 -> 0 | Q38: =downstream!C$9*Q49 -> 508.46667 | R38: =downstream!D$9*R49 -> 67.421053 | S38: =downstream!E$9*S49 -> 34.5 | T38: =downstream!F$9*T49 -> 21.9 | U38: =downstream!G$9*U49 -> 59.8 | V38: =downstream!H$9*V49 -> 0 | W38: =downstream!I$9*W49 -> 43 | X38: =SUM(P38:W38) -> 735.08772 | Y38: =downstream!K$9*L49 -> 272.38256
D39: Semi | E39: =Y50 -> 8458.9891 | F39: =W27 -> 1186.46 | G39: =Y24 -> 853.08 | H39: =Y51 -> 8792.3691 | I39: =E39+F39-G39 -> 8792.3691 | J39: =E39-G39 -> 7605.9091 | M39: =SUM(M36:M38) -> 4685 | O39: sum (lb) | P39: =SUM(P32:P38) -> 3185 | Q39: =SUM(Q32:Q38) -> 5005 | R39: =SUM(R32:R38) -> 2602 | S39: =SUM(S32:S38) -> 1598 | T39: =SUM(T32:T38) -> 1932 | U39: =SUM(U32:U38) -> 1661 | V39: =SUM(V32:V38) -> 4967 | W39: =SUM(W32:W38) -> 687 | ... Y39: =SUM(Y32:Y38) -> 2763 | Z39: =SUM(X39:Y39) -> 24400
D40: Final | E40: =X24 -> 7710.6565 | F40: =end_use!N10 -> 2545.5824 | G40: =end_use!O10 -> 1235.1578 | H40: =end_use!P10 -> 9021.0811 | I40: =E40+F40-G40 -> 9021.0811 | J40: =E40-G40 -> 6475.4987 | O40: sum(kg) | P40: =P39*0.453592 -> 1444.6905 | Q40: =Q39*0.453592 -> 2270.228 | R40: =R39*0.453592 -> 1180.2464 | S40: =S39*0.453592 -> 724.84002 | T40: =T39*0.453592 -> 876.33974 | U40: =U39*0.453592 -> 753.41631 | V40: =V39*0.453592 -> 2252.9915 | W40: =W39*0.453592 -> 311.6177 | ... Y40: =Y39*0.453592 -> 1253.2747 | Z40: =SUM(X40:Y40) -> 11067.645
O41: Adjust_factor | P41: =331449281/(331449281+38526760) -> 0.89586688 | Q41: =331449281/(331449281+38526760) -> 0.89586688 | R41: =331449281/(331449281+38526760) -> 0.89586688 | S41: =331449281/(331449281+38526760) -> 0.89586688 | T41: =331449281/(331449281+38526760) -> 0.89586688 | U41: =331449281/(331449281+38526760) -> 0.89586688 | V41: =331449281/(331449281+38526760) -> 0.89586688 | W41: =331449281/(331449281+38526760) -> 0.89586688 | X41: =331449281/(331449281+38526760) -> 0.89586688 | Y41: 1 | AB41: US semi received | AC41: US semi import
...

Sheet upstream
A1: Bayer (M) | B1: Metallurgical Bauxite inflow | D1: outflow | F1: Oxide for Al industry | G1: Efficiency | H1: Al in Al2O3 | I1: Al in Alumina | J1: Al in Bauxite | K1: EoL | L1: index | M1: amount | N1: note
A2: 0 | B2: Domestically mined | C2: =C4*A2 -> 0 | D2: M-E | E2: =E5*F2 -> 385.41176 | F2: 0.56 | G2: =1000*H2/(2234*J2) -> 0.94791722 | H2: =54/102 -> 0.52941176 | I2: =1/1.917 -> 0.52164841 | J2: =1/4 -> 0.25 | L2: collected | M2: =end_use!I10 -> 4384.3729 | N2: EoL domestically collected | Q2: R1 target | R2: =W11 -> 6812.742 | S2: R1.EoL_scrap rate | T2: =U12 -> 0.16573175 | V2: dom-R1 | W2: =R2*T2 -> 1129.0877 | Y2: =W2/M2 -> 0.25752546 | Z2: Upcycling rate | AA2: =CONCATENATE("[",TEXT(AA20,"0.000"), ", ", TEXT(AA32,"0.000"),"]") -> [0.000, 0.000]
A3: =1-A2 -> 1 | B3: Metallurgical bauxite Import | C3: =C4-C2 -> 726.05 | D3: M Trade | E3: =E5-E2 -> 302.82353 | H3: =1/H2 -> 1.8888889 | I3: =1/I2 -> 1.917 | L3: export | M3: =M2-W2-W3 -> 1894.6816 | N3: EoL scrap export | O3: 1850 | Q3: R2 target | R3: =W23 -> 2100.5074 | S3: R2.EoL_scrap_rate | T3: =U24 -> 0.64775 | V3: dom-R2 | W3: =R3*T3 -> 1360.6037 | AA3: ="lowerbound: " & TEXT(AA17,"0") -> lowerbound: 0
B4: Total | C4: =E5/G2 -> 726.05 | D4: loss | E4: =C4*(1-G2) -> 37.814706 | L4: import | M4: =W13+W25 -> 1369.2421 | N4: pre-consumer scrap import | O4: 542 | S4: Recycled/Collected | T4: =M5/M2 -> 0.56785574 | U4: =0.717 -> 0.717 | V4: import-R1 | W4: =W13 -> 1091.8433 | AA4: ="lowerbound: " & TEXT(AA29,"0") -> lowerbound: 0
D5: Value Outflow | E5: =1300*H2 -> 688.23529 | L5: EoL inflow | M5: =M2-M3 -> 2489.6913 | N5: Domestic EoL recycled | S5: Export/Collected | T5: =M3/M2 -> 0.43214426 | U5: =1-U4 -> 0.283 | V5: import-R2 | W5: =W25 -> 277.39877
L6: External scrap | M6: =M5+M4 -> 3858.9334 | N6: Total scrap recycled: domestic + import | S6: PCRR (recycled/Available) | T6: =Q8/M7 -> 0.4398685
A7: E | B7: inflow | D7: outflow | F7: E-C1 | G7: E-C2 | H7: E-R1 | I7: E-R2 | J7: Efficiency | L7: Available | M7: =end_use!H10 -> 5660.0809 | S7: PCRC (recyced content/alloy) | T7: 0.24550098 | V7: External-R1 | W7: =W2+W4 -> 2220.931
B8: dom alumina (M-E) | C8: =E2 -> 385.41176 | D8: Primary production | E8: 1010 | F8: =L19 -> 715.80655 | G8: =L28 -> 231.48744 | H8: =(E8-F8-G8)*H9 -> 31.353004 | I8: =E8-F8-G8-H8 -> 31.353004 | J8: =I2/H2 -> 0.98533588 | L8: Alloy produced | M8: =J17+J26 -> 9634.2051 | N8: Recycled content in alloys | O8: =M8*T7 -> 2365.2067 | P8: Recycled Post-consumer | Q8: =O8/O19 -> 2489.6913 | V8: External-R2 | W8: =W3+W5 -> 1638.0024
B9: Metallurical alumina import | C9: =C10-C8 -> 639.61941 | D9: loss | E9: =E10-E8 -> 15.031176 | H9: 0.5 | I9: =1-H9 -> 0.5 | N9: From R2 | O9: =N26*U24 -> 1292.5735 | T9: Adjust X1 to make align import scrap, export scrap, and scrap recycling rate with reference
B10: total | C10: =E10 -> 1025.0312 | D10: total | E10: =E8/J8 -> 1025.0312 | N10: From R1 | O10: =O8-O9 -> 1072.6333 | T10: x1 boundaries | U10: ="[" & TEXT(W12/W11,"0.0%") & ", " & TEXT(1-U13,"0.0%") & "]" -> [46.6%, 79.2%]
S11: R1 (Refiner) | T11: presorted_scrap_ratio (u%) | U11: =1-U13-U12 -> 0.62627122 | V11: Inflow target | W11: =P17/U13 -> 6812.742
A12: C1 | B12: wrough alloy ingots to | C12: semi produced | D12: ingot consumed | E12: dom-to-dom | F12: Dom Alloy% | G12: import | H12: export | I12: export/production | J12: Alloy produced | L12: Casting Virgin (E - C1) | M12: Direct Primary/kg-ingot | N12: Remelted (R1-C1) | O12: kg sweetener/kg-ingot | P12: Sweetener | S12: Produce secondary wrought alloys | T12: EoL_scrap_ratio (v%) | U12: =O10/N17 -> 0.16573175 | V12: pre-consumer scrap | W12: =SUM(Raw!E9:E23) -> 3174.781
B13: Rolling (F1) | C13: =Raw!AE9 -> 4025.3285 | D13: =Raw!AC9 -> 5688.0631 | E13: =D13*F13 -> 4834.8536 | F13: 0.85 | G13: =D13-E13 -> 853.20946 | H13: =E13*I13 -> 61.046131 | I13: =1/(100-19.8-1) -> 0.012626263 | J13: =E13+H13 -> 4895.8997 | L13: =J13*M13 -> 400.38668 | M13: =28.2%*0.29 -> 0.08178 | N13: =J13-L13 -> 4495.5131 | O13: =0.2052 -> 0.2052 | P13: =J13*O13 -> 1004.6386 | T13: sweetener_ratio (w%) | U13: =O18*O19 -> 0.20799703 | V13: import scrap | W13: =W14-W12 -> 1091.8433
B14: Extrusion (F2) | C14: =Raw!AE10 -> 1769.7135 | D14: =Raw!AC10 -> 2396.2 | E14: =D14*F14 -> 1916.96 | F14: =(100-19.8-1)/99 -> 0.8 | G14: =D14-E14 -> 479.24 | H14: =E14*I14 -> 24.20404 | I14: =1/(100-19.8-1) -> 0.012626263 | J14: =E14+H14 -> 1941.164 | L14: =J14*M14 -> 379.89953 | M14: =15.5/(15.5+63.7) -> 0.19570707 | N14: =J14-L14 -> 1561.2645 | O14: =0.3635-M14 -> 0.16779293 | P14: =J14*O14 -> 325.7136 | V14: presorted scrap | W14: =W11*U11 -> 4266.6243
B15: Wire Drawing (F3) | C15: =Raw!AE11 -> 349.34729 | D15: =Raw!AC11 -> 473.01779 | E15: =D15*F15 -> 378.41423 | F15: =F14 -> 0.8 | G15: =D15-E15 -> 94.603558 | H15: =E15*I15 -> 4.7779575 | I15: =1/(100-19.8-1) -> 0.012626263 | J15: =E15+H15 -> 383.19219 | L15: =J15*M15 -> 75.105669 | M15: 0.196 | N15: =J15-L15 -> 308.08652 | O15: =O14 -> 0.16779293 | P15: =J15*O15 -> 64.29694 | V15: post-consumer-scrap | W15: =W2 -> 1129.0877
B16: Forging and Powdering (F4) | C16: =Raw!AE12 -> 131.72096 | D16: =Raw!AC12 -> 164.6512 | E16: =D16*F16 -> 131.72096 | F16: =F14 -> 0.8 | G16: =D16-E16 -> 32.930239 | H16: =E16*I16 -> 1.6631434 | I16: =1/(100-19.8-1) -> 0.012626263 | J16: =E16+H16 -> 133.3841 | L16: =J16*M16 -> 26.143284 | M16: 0.196 | N16: =J16-L16 -> 107.24082 | O16: =O14 -> 0.16779293 | P16: =J16*O16 -> 22.380909 | V16: dom sweetener | W16: =H8 -> 31.353004 | X16: actual scrap inflow | Y16: =W14+W15 -> 5395.7119
D17: =SUM(D13:D16) -> 8721.932 | E17: =SUM(E13:E16) -> 7261.9488 | G17: =SUM(G13:G16) -> 1459.9833 | H17: =SUM(H13:H16) -> 91.691272 | J17: =SUM(J13:J16) -> 7353.64 | L17: =SUM(L13:L16) -> 881.53516 | N17: =SUM(N13:N16) -> 6472.1049 | O17: =P17/J17 -> 0.19269777 | P17: =SUM(P13:P16) -> 1417.0301 | V17: metal import | W17: =P17-H8 -> 1385.6771 | X17: sweetener | Y17: =W16+W17 -> 1417.0301
K18: Dom virgin metal % | L18: 0.812 | M18: =E8/(L17+L26) -> 0.86575024 | O18: =P17/N17 -> 0.21894424 | P18: kg sweet/kg remelted metal | V18: total inflow or outflow | W18: =SUM(W14:W17) -> 6812.742 | X18: kg sweet/kg-in | Y18: =Y17/W18 -> 0.20799703 | Z18: Actual kg scrap/kg-in | AA18: =Y16/W18 -> 0.79200297
K19: Dom virgin metal | L19: =L17*L18 -> 715.80655 | M19: =(L19<E8) -> TRUE | O19: 0.95 | P19: R1 Efficiency | V19: valuable outflow | W19: =N17 -> 6472.1049 | X19: kg sweet/kg-out | Y19: =Y17/W19 -> 0.21894424 | Z19: Min kg scrap/kg-ingot-out | AA19: =1-Y19 -> 0.78105576
K20: Imported virgin metal | L20: =L17-L19 -> 165.72861 | V20: loss | W20: =W18-W19 -> 340.6371 | X20: efficiency | Y20: =W19/W18 -> 0.95
T21: =T9 -> Adjust X1 to make align import scrap, export scrap, and scrap recycling rate with reference
A22: C2 | B22: foundry alloy ingots to | C22: semi produced | D22: ingot consumed | E22: dom-to-dom | F22: Dom Alloy % | G22: import | H22: export | I22: export/production | J22: Alloy produced | L22: Casting Virgin (E - C2) | M22: Direct Primary% | N22: Recycled (R2-C2) | O22: kg sweetener/kg-ingot | P22: Sweetener | T22: x1 boundaries | U22: ="[" & TEXT(W24/W23,"0.0%") & ", " & TEXT(1-U25,"0.0%") & "]" -> [16.8%, 94.8%]
B23: Die casting (SC1) | C23: =Raw!AE13 -> 1091.6773 | D23: =Raw!AC13 -> 1140.9098 | E23: =D23*F23 -> 1083.8643 | F23: 0.95 | G23: =D23-E23 -> 57.045491 | H23: =(205-$H$17)*I23 -> 56.666711 | I23: =Raw!L47 -> 0.50010897 | J23: =E23+H23 -> 1140.531 | L23: =J23*M23 -> 171.07966 | M23: =0.15 -> 0.15 | N23: =J23-L23 -> 969.45139 | O23: =0.055*(1-M23) -> 0.04675 | P23: =J23*O23 -> 53.319826 | S23: R2 (Remelter) | T23: presorted_scrap_ratio (u) | U23: 0.3 | V23: inflow target | W23: =P26/U25 -> 2100.5074
B24: Perm. Mold Castings (SC2) | C24: =Raw!AE14 -> 748.70265 | D24: =Raw!AC14 -> 782.46768 | E24: =D24*F24 -> 743.34429 | F24: 0.95 | G24: =D24-E24 -> 39.123384 | H24: =(205-$H$17)*I24 -> 38.863606 | I24: =Raw!L48 -> 0.34298863 | J24: =E24+H24 -> 782.2079 | L24: =J24*M24 -> 78.22079 | M24: =M23-0.05 -> 0.1 | N24: =J24-L24 -> 703.98711 | O24: =0.055*(1-M24) -> 0.0495 | P24: =J24*O24 -> 38.719291 | S24: Produce secondary foundry alloys | T24: EoL_scrap_ratio (v) | U24: =1-U23-U25 -> 0.64775 | V24: pre-consumer scrap | W24: =SUM(Raw!F9:F23) -> 352.75344
B25: Sand Castings (SC3) | C25: =Raw!AE15 -> 342.49893 | D25: =Raw!AC15 -> 357.94496 | E25: =D25*F25 -> 340.04771 | F25: 0.95 | G25: =D25-E25 -> 17.897248 | H25: =(205-$H$17)*I25 -> 17.778411 | I25: =Raw!L49 -> 0.15690239 | J25: =E25+H25 -> 357.82612 | L25: =J25*M25 -> 35.782612 | M25: =M24 -> 0.1 | N25: =J25-L25 -> 322.04351 | O25: =0.055*(1-M25) -> 0.0495 | P25: =J25*O25 -> 17.712393 | T25: sweetener_ratio (w) | U25: =O27*O28 -> 0.05225 | V25: import scrap | W25: =W26-W24 -> 277.39877
D26: =SUM(D23:D25) -> 2281.3225 | E26: =SUM(E23:E25) -> 2167.2563 | G26: =SUM(G23:G25) -> 114.06612 | H26: =SUM(H23:H25) -> 113.30873 | J26: =SUM(J23:J25) -> 2280.5651 | L26: =SUM(L23:L25) -> 285.08306 | N26: =SUM(N23:N25) -> 1995.482 | O26: =P26/J26 -> 0.0481247 | P26: =SUM(P23:P25) -> 109.75151 | V26: presorted scrap | W26: =W23*U23 -> 630.15221
K27: Dom virgin metal % | L27: =L18 -> 0.812 | O27: =P26/N26 -> 0.055 | P27: kg sweet/kg recycled metal | V27: post-consumer-scrap | W27: =W3 -> 1360.6037
G28: import | H28: export | I28: consumed | J28: produced | K28: Dom virgin metal | L28: =L26*L27 -> 231.48744 | O28: 0.95 | P28: R2 Efficiency | V28: dom sweetener | W28: =I8 -> 31.353004 | X28: actual scrap inflow | Y28: =W26+W27 -> 1990.7559
F29: Alloy ingot | G29: =G17+G26 -> 1574.0494 | H29: =H17+H26 -> 205 | I29: =D17+D26 -> 11003.254 | J29: =J17+J26 -> 9634.2051 | K29: Imported virgin metal | L29: =L26-L28 -> 53.595615 | V29: metal import | W29: =P26-I8 -> 78.398506 | X29: sweetener | Y29: =W28+W29 -> 109.75151
V30: total inflow or outflow | W30: =SUM(W26:W29) -> 2100.5074 | X30: kg sweet/kg-in | Y30: =Y29/W30 -> 0.05225 | Z30: Actual kg scrap/kg-in | AA30: =Y28/W30 -> 0.94775
A31: =E17+E26 -> 9429.2051 | C31: Current | D31: Benchmark | V31: valuable outflow | W31: =N26 -> 1995.482 | X31: kg sweet/kg-out | Y31: =Y29/W31 -> 0.055 | Z31: Min kg scrap/kg-ingot-out | AA31: =1-Y31 -> 0.945
B32: Alloy consumed | C32: =D17+D26+C36 -> 11208.254 | D32: =C32 -> 11208.254 | V32: loss | W32: =W30-W31 -> 105.02537 | X32: efficiency | Y32: =W31/W30 -> 0.95 | Z32: Should be fine-tuned to 95%
B33: dom-to-dom alloy % | C33: =C34/(C34+C35) -> 0.85694693 | D33: 0.705 | E33: =1-E48/D32 -> 0.70825074 | F33: Lowerbound
B34: Dom-to-dom alloys | C34: =E17+E26 -> 9429.2051 | D34: =D32*D33 -> 7901.8194
B35: Alloy import required | C35: =G17+G26 -> 1574.0494 | D35: =D32*(1-D33) -> 3306.4351 | T35: Casting virgin Consumption | U35: =L17+L26 -> 1166.6182 | V35: Dom. Casting Virgin | W35: =F8+G8 -> 947.29399 | X35: Import Casting Virgin | Y35: =U35-W35 -> 219.32422
B36: Export | C36: 205 | D36: 205 | T36: Sweetener Consumption | U36: =P17+P26 -> 1526.7816 | V36: Dom. Sweetener | W36: =H8+I8 -> 62.706008 | X36: Import Sweetener | Y36: =U36-W36 -> 1464.0756
A37: =L19 -> 715.80655 | T37: Virgin Metal Consumption | U37: =U35+U36 -> 2693.3998 | W37: =SUM(W35:W36) -> 1010 | Y37: =SUM(Y35:Y36) -> 1683.3998
B38: Available primary | C38: =E8 -> 1010 | D38: =C38 -> 1010 | S38: =U38/U37 -> 0.62500925 | T38: Virgin Metal import | U38: =W17+W29+L20+L29 -> 1683.3998
A39: =N17+N26 -> 8467.5869 | B39: direct primary/ingot inflow | C39: =(L17+L26)/(D17+D26) -> 0.10602483 | D39: 0.13 | E39: =D38/E17 -> 0.13908112 | F39: Upperbound | T39: Alloy import | U39: =G17+G26 -> 1574.0494
B40: dom-to-dom direct primary | C40: =(D17+D26)*C39 -> 1166.6182 | D40: =E17*D39 -> 944.05334 | T40: Crude import | U40: =U38+U39 -> 3257.4492
...

Sheet downstream
A1: Table 4 | B1: P1 | C1: P2 | D1: P3 | E1: P4 | F1: P5 | G1: P6 | H1: P7 | I1: P8
A2: US & Canada Received (lbs) | B2: Construction | C2: Trans. Auto | D2: Trans. Other | E2: Durables | F2: Electrical | G2: Machinery | H2: Container | I2: Other | J2: Received | K2: Export | L2: Total | N2: Table S8: Semi-Composition | O2: =B2 -> Construction | P2: =C2 -> Trans. Auto | Q2: =D2 -> Trans. Other | R2: =E2 -> Durables | S2: =F2 -> Electrical | T2: =G2 -> Machinery | U2: =H2 -> Container | V2: =I2 -> Other
A3: Sheet | B3: 1199 | C3: =1720 -> 1720 | D3: =2878-C3 -> 1158 | E3: 505 | F3: 324 | G3: 565 | H3: 4022 | I3: 63 | J3: =SUM(B3:I3) -> 9556 | K3: 533 | L3: =SUM(J3:K3) -> 10089 | N3: Sheet | O3: =B3/B$10 -> 0.37645212 | P3: =C3/C$10 -> 0.34365634 | Q3: =D3/D$10 -> 0.44504228 | R3: =E3/E$10 -> 0.31602003 | S3: =F3/F$10 -> 0.16770186 | T3: =G3/G$10 -> 0.34015653 | U3: =H3/H$10 -> 0.80974431 | V3: =I3/I$10 -> 0.091703057
A4: Foil | B4: 38 | C4: 70 | D4: =86-C4 -> 16 | E4: 254 | F4: 11 | G4: 5 | H4: 944 | I4: 2 | J4: =SUM(B4:I4) -> 1340 | K4: 99 | L4: =SUM(J4:K4) -> 1439 | N4: Foil | O4: =B4/B$10 -> 0.011930926 | P4: =C4/C$10 -> 0.013986014 | Q4: =D4/D$10 -> 0.0061491161 | R4: =E4/E$10 -> 0.15894869 | S4: =F4/F$10 -> 0.0056935818 | T4: =G4/G$10 -> 0.0030102348 | U4: =H4/H$10 -> 0.19005436 | V4: =I4/I$10 -> 0.0029112082
A5: Extrusions | B5: =1884 -> 1884 | C5: =59+352+97 -> 508 | D5: =1354-C5 -> 846 | E5: 471 | F5: 470 | G5: 469 | H5: 0 | I5: 79 | J5: =SUM(B5:I5) -> 4727 | K5: =300+50 -> 350 | L5: =SUM(J5:K5) -> 5077 | N5: Extrusions | O5: =B5/B$10 -> 0.59152276 | P5: =C5/C$10 -> 0.1014985 | Q5: =D5/D$10 -> 0.32513451 | R5: =E5/E$10 -> 0.29474343 | S5: =F5/F$10 -> 0.24327122 | T5: =G5/G$10 -> 0.28236002 | U5: =H5/H$10 -> 0 | V5: =I5/I$10 -> 0.11499272
A6: Cable/Wire | B6: 28 | C6: 4 | D6: =18-C6 -> 14 | E6: 5 | F6: =11+460+436 -> 907 | G6: 14 | H6: 1 | I6: 5 | J6: =SUM(B6:I6) -> 978 | K6: =17+1 -> 18 | L6: =SUM(J6:K6) -> 996 | N6: Cable/Wire | O6: =B6/B$10 -> 0.0087912088 | P6: =C6/C$10 -> 0.0007992008 | Q6: =D6/D$10 -> 0.0053804766 | R6: =E6/E$10 -> 0.0031289111 | S6: =F6/F$10 -> 0.4694617 | T6: =G6/G$10 -> 0.0084286574 | U6: =H6/H$10 -> 0.00020132877 | V6: =I6/I$10 -> 0.0072780204
A7: Forgings | B7: 0 | C7: 73 | D7: =214-C7 -> 141 | E7: 18 | F7: 1 | G7: 10 | H7: 0 | I7: 7 | J7: =SUM(B7:I7) -> 250 | K7: 16 | L7: =SUM(J7:K7) -> 266 | N7: Forgings | O7: =B7/B$10 -> 0 | P7: =C7/C$10 -> 0.014585415 | Q7: =D7/D$10 -> 0.054189085 | R7: =E7/E$10 -> 0.01126408 | S7: =F7/F$10 -> 0.00051759834 | T7: =G7/G$10 -> 0.0060204696 | U7: =H7/H$10 -> 0 | V7: =I7/I$10 -> 0.010189229
A8: Powders | B8: 0 | C8: 0 | D8: 0 | E8: 0 | F8: 0 | G8: 0 | H8: 0 | I8: 101 | J8: =SUM(B8:I8) -> 101 | K8: 11 | L8: =SUM(J8:K8) -> 112 | N8: Powders | O8: =B8/B$10 -> 0 | P8: =C8/C$10 -> 0 | Q8: =D8/D$10 -> 0 | R8: =E8/E$10 -> 0 | S8: =F8/F$10 -> 0 | T8: =G8/G$10 -> 0 | U8: =H8/H$10 -> 0 | V8: =I8/I$10 -> 0.14701601
A9: Shape Castings | B9: 36 | C9: 2630 | D9: =3057-C9 -> 427 | E9: 345 | F9: 219 | G9: 598 | H9: 0 | I9: 430 | J9: =SUM(B9:I9) -> 4685 | K9: 1736 | L9: =SUM(J9:K9) -> 6421 | N9: Shape Castings | O9: =B9/B$10 -> 0.011302983 | P9: =C9/C$10 -> 0.52547453 | Q9: =D9/D$10 -> 0.16410453 | R9: =E9/E$10 -> 0.21589487 | S9: =F9/F$10 -> 0.11335404 | T9: =G9/G$10 -> 0.36002408 | U9: =H9/H$10 -> 0 | V9: =I9/I$10 -> 0.62590975
A10: Total | B10: =SUM(B3:B9) -> 3185 | C10: =SUM(C3:C9) -> 5005 | D10: =SUM(D3:D9) -> 2602 | E10: =SUM(E3:E9) -> 1598 | F10: =SUM(F3:F9) -> 1932 | G10: =SUM(G3:G9) -> 1661 | H10: =SUM(H3:H9) -> 4967 | I10: =SUM(I3:I9) -> 687 | ... K10: =SUM(K3:K9) -> 2763 | L10: =SUM(J10:K10) -> 24400 | O10: =SUM(O3:O9) -> 1 | P10: =SUM(P3:P9) -> 1 | Q10: =SUM(Q3:Q9) -> 1 | R10: =SUM(R3:R9) -> 1 | S10: =SUM(S3:S9) -> 1 | T10: =SUM(T3:T9) -> 1 | U10: =SUM(U3:U9) -> 1 | V10: =SUM(V3:V9) -> 1
J11: =SUM(B10:I10) -> 21637 | L11: =SUM(J3:K9) -> 24400
K12: Adjustment factor | O12: =O2 -> Construction | P12: =P2 -> Trans. Auto | Q12: =Q2 -> Trans. Other | R12: =R2 -> Durables | S12: =S2 -> Electrical | T12: =T2 -> Machinery | U12: =U2 -> Container | V12: =V2 -> Other
A13: US Received (kg) | B13: =B2 -> Construction | C13: =C2 -> Trans. Auto | D13: =D2 -> Trans. Other | E13: =E2 -> Durables | F13: =F2 -> Electrical | G13: =G2 -> Machinery | H13: =H2 -> Container | I13: =I2 -> Other | J13: Total | K13: =331449281/(331449281+38526760) -> 0.89586688 | N13: Process | O13: P1 | P13: P2 | Q13: P3 | R13: P4 | S13: P5 | T13: P6 | U13: P7 | V13: P8
A14: Sheet | B14: =B3*0.453592*$K$13 -> 487.2233 | C14: =C3*0.453592*$K$13 -> 698.93584 | D14: =D3*0.453592*$K$13 -> 470.56262 | E14: =E3*0.453592*$K$13 -> 205.21081 | F14: =F3*0.453592*$K$13 -> 131.66001 | G14: =G3*0.453592*$K$13 -> 229.5923 | H14: =H3*0.453592*$K$13 -> 1634.3721 | I14: =I3*0.453592*$K$13 -> 25.600557 | J14: =SUM(B14:I14) -> 3883.1575 | M14: Sheet and Foil | N14: F1 | O14: =O3+O4 -> 0.38838305 | P14: =P3+P4 -> 0.35764236 | Q14: =Q3+Q4 -> 0.45119139 | R14: =R3+R4 -> 0.47496871 | S14: =S3+S4 -> 0.17339545 | T14: =T3+T4 -> 0.34316677 | U14: =U3+U4 -> 0.99979867 | V14: =V3+V4 -> 0.094614265
A15: Foil | B15: =B4*0.453592*$K$13 -> 15.441606 | C15: =C4*0.453592*$K$13 -> 28.445063 | D15: =D4*0.453592*$K$13 -> 6.5017288 | E15: =E4*0.453592*$K$13 -> 103.21494 | F15: =F4*0.453592*$K$13 -> 4.4699385 | G15: =G4*0.453592*$K$13 -> 2.0317902 | H15: =H4*0.453592*$K$13 -> 383.602 | I15: =I4*0.453592*$K$13 -> 0.8127161 | J15: =SUM(B15:I15) -> 544.51979 | M15: Extrusions | N15: F2 | O15: =O5 -> 0.59152276 | P15: =P5 -> 0.1014985 | Q15: =Q5 -> 0.32513451 | R15: =R5 -> 0.29474343 | S15: =S5 -> 0.24327122 | T15: =T5 -> 0.28236002 | U15: =U5 -> 0 | V15: =V5 -> 0.11499272
A16: Extrusions | B16: =B5*0.453592*$K$13 -> 765.57856 | C16: =C5*0.453592*$K$13 -> 206.42989 | D16: =D5*0.453592*$K$13 -> 343.77891 | E16: =E5*0.453592*$K$13 -> 191.39464 | F16: =F5*0.453592*$K$13 -> 190.98828 | G16: =G5*0.453592*$K$13 -> 190.58193 | H16: =H5*0.453592*$K$13 -> 0 | I16: =I5*0.453592*$K$13 -> 32.102286 | J16: =SUM(B16:I16) -> 1920.8545 | M16: Cable/Wire | N16: F3 | O16: =O6 -> 0.0087912088 | P16: =P6 -> 0.0007992008 | Q16: =Q6 -> 0.0053804766 | R16: =R6 -> 0.0031289111 | S16: =S6 -> 0.4694617 | T16: =T6 -> 0.0084286574 | U16: =U6 -> 0.00020132877 | V16: =V6 -> 0.0072780204
A17: Cable/Wire | B17: =B6*0.453592*$K$13 -> 11.378025 | C17: =C6*0.453592*$K$13 -> 1.6254322 | D17: =D6*0.453592*$K$13 -> 5.6890127 | E17: =E6*0.453592*$K$13 -> 2.0317902 | F17: =F6*0.453592*$K$13 -> 368.56675 | G17: =G6*0.453592*$K$13 -> 5.6890127 | H17: =H6*0.453592*$K$13 -> 0.40635805 | I17: =I6*0.453592*$K$13 -> 2.0317902 | J17: =SUM(B17:I17) -> 397.41817 | M17: Forgings and Powder | N17: F4 | O17: =O7+O8 -> 0 | P17: =P7+P8 -> 0.014585415 | Q17: =Q7+Q8 -> 0.054189085 | R17: =R7+R8 -> 0.01126408 | S17: =S7+S8 -> 0.00051759834 | T17: =T7+T8 -> 0.0060204696 | U17: =U7+U8 -> 0 | V17: =V7+V8 -> 0.15720524
A18: Forgings | B18: =B7*0.453592*$K$13 -> 0 | C18: =C7*0.453592*$K$13 -> 29.664138 | D18: =D7*0.453592*$K$13 -> 57.296485 | E18: =E7*0.453592*$K$13 -> 7.3144449 | F18: =F7*0.453592*$K$13 -> 0.40635805 | G18: =G7*0.453592*$K$13 -> 4.0635805 | H18: =H7*0.453592*$K$13 -> 0 | I18: =I7*0.453592*$K$13 -> 2.8445063 | J18: =SUM(B18:I18) -> 101.58951 | L18: =Raw!L47 -> 0.50010897 | M18: Die Casting | N18: SC1 | O18: =O$9*$L18 -> 0.0056527231 | P18: =P$9*$L18 -> 0.26279452 | Q18: =Q$9*$L18 -> 0.08207015 | R18: =R$9*$L18 -> 0.10797096 | S18: =S$9*$L18 -> 0.056689371 | T18: =T$9*$L18 -> 0.18005127 | U18: =U$9*$L18 -> 0 | V18: =V$9*$L18 -> 0.31302308
A19: Powders | B19: =B8*0.453592*$K$13 -> 0 | C19: =C8*0.453592*$K$13 -> 0 | D19: =D8*0.453592*$K$13 -> 0 | E19: =E8*0.453592*$K$13 -> 0 | F19: =F8*0.453592*$K$13 -> 0 | G19: =G8*0.453592*$K$13 -> 0 | H19: =H8*0.453592*$K$13 -> 0 | I19: =I8*0.453592*$K$13 -> 41.042163 | J19: =SUM(B19:I19) -> 41.042163 | L19: =Raw!L48 -> 0.34298863 | M19: Permanent Mold Castings | N19: SC2 | O19: =O$9*$L19 -> 0.0038767946 | P19: =P$9*$L19 -> 0.18023179 | Q19: =Q$9*$L19 -> 0.05628599 | R19: =R$9*$L19 -> 0.074049486 | S19: =S$9*$L19 -> 0.038879146 | T19: =T$9*$L19 -> 0.12348417 | U19: =U$9*$L19 -> 0 | V19: =V$9*$L19 -> 0.21467993
A20: Shape Castings | B20: =B9*0.453592*$K$13 -> 14.62889 | C20: =C9*0.453592*$K$13 -> 1068.7217 | D20: =D9*0.453592*$K$13 -> 173.51489 | E20: =E9*0.453592*$K$13 -> 140.19353 | F20: =F9*0.453592*$K$13 -> 88.992413 | G20: =G9*0.453592*$K$13 -> 243.00211 | H20: =H9*0.453592*$K$13 -> 0 | I20: =I9*0.453592*$K$13 -> 174.73396 | J20: =SUM(B20:I20) -> 1903.7875 | L20: =Raw!L49 -> 0.15690239 | M20: Sand Casting | N20: SC3 | O20: =O$9*$L20 -> 0.0017734651 | P20: =P$9*$L20 -> 0.082448211 | Q20: =Q$9*$L20 -> 0.025748395 | R20: =R$9*$L20 -> 0.033874422 | S20: =S$9*$L20 -> 0.01778552 | T20: =T$9*$L20 -> 0.056488641 | U20: =U$9*$L20 -> 0 | V20: =V$9*$L20 -> 0.098206739
A21: =A10 -> Total | B21: =SUM(B14:B20) -> 1294.2504 | C21: =SUM(C14:C20) -> 2033.822 | D21: =SUM(D14:D20) -> 1057.3436 | E21: =SUM(E14:E20) -> 649.36016 | F21: =SUM(F14:F20) -> 785.08375 | G21: =SUM(G14:G20) -> 674.96072 | H21: =SUM(H14:H20) -> 2018.3804 | I21: =SUM(I14:I20) -> 279.16798 | J21: =SUM(B21:I21) -> 8792.3691 | O21: =SUM(O14:O20) -> 1 | P21: =SUM(P14:P20) -> 1 | Q21: =SUM(Q14:Q20) -> 1 | R21: =SUM(R14:R20) -> 1 | S21: =SUM(S14:S20) -> 1 | T21: =SUM(T14:T20) -> 1 | U21: =SUM(U14:U20) -> 1 | V21: =SUM(V14:V20) -> 1
A24: Table S9: Yield efficiencies of Fabrication | B24: =B2 -> Construction | C24: =C2 -> Trans. Auto | D24: =D2 -> Trans. Other | E24: =E2 -> Durables | F24: =F2 -> Electrical | G24: =G2 -> Machinery | H24: =H2 -> Container | I24: =I2 -> Other | O24: =O2 -> Construction | P24: =P2 -> Trans. Auto | Q24: =Q2 -> Trans. Other | R24: =R2 -> Durables | S24: =S2 -> Electrical | T24: =T2 -> Machinery | U24: =U2 -> Container | V24: =V2 -> Other
A25: =A14 -> Sheet | B25: =5/6 -> 0.83333333 | C25: =0.657894736842105 -> 0.65789474 | D25: 0.65789474 | E25: 0.76923077 | F25: 0.76923077 | G25: 0.76923077 | H25: 0.82644628 | I25: 0.76923077 | M25: Yield efficiencies | N25: Process | O25: P1 | P25: P2 | Q25: P3 | R25: P4 | S25: P5 | T25: P6 | U25: P7 | V25: P8
A26: =A15 -> Foil | B26: =10/11 -> 0.90909091 | C26: =5/6 -> 0.83333333 | D26: =5/6 -> 0.83333333 | E26: =5/6 -> 0.83333333 | F26: =5/6 -> 0.83333333 | G26: =5/6 -> 0.83333333 | H26: =10/11 -> 0.90909091 | I26: =5/6 -> 0.83333333 | M26: Sheet and Foil | N26: F1 | O26: =(B14*B25+B15*B26)/(B14+B15) -> 0.83566057 | P26: =(C14*C25+C15*C26)/(C14+C15) -> 0.66475546 | Q26: =(D14*D25+D15*D26)/(D14+D15) -> 0.66028572 | R26: =(E14*E25+E15*E26)/(E14+E15) -> 0.79068275 | S26: =(F14*F25+F15*F26)/(F14+F15) -> 0.77133563 | T26: =(G14*G25+G15*G26)/(G14+G15) -> 0.76979307 | U26: =(H14*H25+H15*H26)/(H14+H15) -> 0.84215642 | V26: =(I14*I25+I15*I26)/(I14+I15) -> 0.77120316
A27: =A16 -> Extrusions | B27: 0.95057034 | C27: =B27 -> 0.95057034 | D27: =C27 -> 0.95057034 | E27: =D27 -> 0.95057034 | F27: =E27 -> 0.95057034 | G27: =F27 -> 0.95057034 | H27: =G27 -> 0.95057034 | I27: =H27 -> 0.95057034 | M27: Extrusions | N27: F2 | O27: =B27 -> 0.95057034 | P27: =C27 -> 0.95057034 | Q27: =D27 -> 0.95057034 | R27: =E27 -> 0.95057034 | S27: =F27 -> 0.95057034 | T27: =G27 -> 0.95057034 | U27: =H27 -> 0.95057034 | V27: =I27 -> 0.95057034
A28: =A17 -> Cable/Wire | B28: =B27 -> 0.95057034 | C28: =C27 -> 0.95057034 | D28: =D27 -> 0.95057034 | E28: =E27 -> 0.95057034 | F28: =F27 -> 0.95057034 | G28: =G27 -> 0.95057034 | H28: =H27 -> 0.95057034 | I28: =I27 -> 0.95057034 | M28: Cable/Wire | N28: F3 | O28: =B28 -> 0.95057034 | P28: =C28 -> 0.95057034 | Q28: =D28 -> 0.95057034 | R28: =E28 -> 0.95057034 | S28: =F28 -> 0.95057034 | T28: =G28 -> 0.95057034 | U28: =H28 -> 0.95057034 | V28: =I28 -> 0.95057034
A29: =A18 -> Forgings | B29: =B28 -> 0.95057034 | C29: =C28 -> 0.95057034 | D29: =D28 -> 0.95057034 | E29: =E28 -> 0.95057034 | F29: =F28 -> 0.95057034 | G29: =G28 -> 0.95057034 | H29: =H28 -> 0.95057034 | I29: =I28 -> 0.95057034 | M29: Forgings and Powder | N29: F4 | O29: =IF(B18+B19>0,(B18*B29+B19*B30)/(B18+B19),0) -> 0 | P29: =IF(C18+C19>0,(C18*C29+C19*C30)/(C18+C19),0) -> 0.95057034 | Q29: =IF(D18+D19>0,(D18*D29+D19*D30)/(D18+D19),0) -> 0.95057034 | R29: =IF(E18+E19>0,(E18*E29+E19*E30)/(E18+E19),0) -> 0.95057034 | S29: =IF(F18+F19>0,(F18*F29+F19*F30)/(F18+F19),0) -> 0.95057034 | T29: =IF(G18+G19>0,(G18*G29+G19*G30)/(G18+G19),0) -> 0.95057034 | U29: =IF(H18+H19>0,(H18*H29+H19*H30)/(H18+H19),0) -> 0 | V29: =IF(I18+I19>0,(I18*I29+I19*I30)/(I18+I19),0) -> 0.99679623
A30: =A19 -> Powders | B30: =B31 -> 1 | C30: =C31 -> 1 | D30: =D31 -> 1 | E30: =E31 -> 1 | F30: =F31 -> 1 | G30: =G31 -> 1 | H30: =H31 -> 1 | I30: =I31 -> 1 | M30: Die Casting | N30: SC1 | O30: =B31 -> 1 | P30: =C31 -> 1 | Q30: =D31 -> 1 | R30: =E31 -> 1 | S30: =F31 -> 1 | T30: =G31 -> 1 | U30: =H31 -> 1 | V30: =I31 -> 1
A31: =A20 -> Shape Castings | B31: 1 | C31: =B31 -> 1 | D31: =C31 -> 1 | E31: =D31 -> 1 | F31: =E31 -> 1 | G31: =F31 -> 1 | H31: =G31 -> 1 | I31: =H31 -> 1 | M31: Permanent Mold Castings | N31: SC2 | O31: =B31 -> 1 | P31: =C31 -> 1 | Q31: =D31 -> 1 | R31: =E31 -> 1 | S31: =F31 -> 1 | T31: =G31 -> 1 | U31: =H31 -> 1 | V31: =I31 -> 1
A32: Aggregate | B32: =B38 -> 0.90650004 | C32: =C38 -> 0.87432486 | D32: =D38 -> 0.82770805 | E32: =E38 -> 0.88530035 | F32: =F38 -> 0.92509491 | G32: =G38 -> 0.90632946 | H32: =H38 -> 0.84217824 | I32: =I38 -> 0.9718051 | M32: Sand Casting | N32: SC3 | O32: =B31 -> 1 | P32: =C31 -> 1 | Q32: =D31 -> 1 | R32: =E31 -> 1 | S32: =F31 -> 1 | T32: =G31 -> 1 | U32: =H31 -> 1 | V32: =I31 -> 1
M33: Aggregate | O33: =SUMPRODUCT(O14:O20,O26:O32) -> 0.90650004 | P33: =SUMPRODUCT(P14:P20,P26:P32) -> 0.87432486 | Q33: =SUMPRODUCT(Q14:Q20,Q26:Q32) -> 0.82770805 | R33: =SUMPRODUCT(R14:R20,R26:R32) -> 0.88530035 | S33: =SUMPRODUCT(S14:S20,S26:S32) -> 0.92509491 | T33: =SUMPRODUCT(T14:T20,T26:T32) -> 0.90632946 | U33: =SUMPRODUCT(U14:U20,U26:U32) -> 0.84217824 | V33: =SUMPRODUCT(V14:V20,V26:V32) -> 0.9718051
O34: =(O33-B38)<0.000001 -> TRUE | P34: =(P33-C38)<0.000001 -> TRUE | Q34: =(Q33-D38)<0.000001 -> TRUE | R34: =(R33-E38)<0.000001 -> TRUE | S34: =(S33-F38)<0.000001 -> TRUE | T34: =(T33-G38)<0.000001 -> TRUE | U34: =(U33-H38)<0.000001 -> TRUE | V34: =(V33-I38)<0.000001 -> TRUE
A35: Fabrication | B35: =B13 -> Construction | C35: =C13 -> Trans. Auto | D35: =D13 -> Trans. Other | E35: =E13 -> Durables | F35: =F13 -> Electrical | G35: =G13 -> Machinery | H35: =H13 -> Container | I35: =I13 -> Other
A36: Semi received | B36: =B21 -> 1294.2504 | C36: =C21 -> 2033.822 | D36: =D21 -> 1057.3436 | E36: =E21 -> 649.36016 | F36: =F21 -> 785.08375 | G36: =G21 -> 674.96072 | H36: =H21 -> 2018.3804 | I36: =I21 -> 279.16798
A37: Product fabricated | B37: =SUMPRODUCT(B14:B20,B25:B31) -> 1173.238 | C37: =SUMPRODUCT(C14:C20,C25:C31) -> 1778.2212 | D37: =SUMPRODUCT(D14:D20,D25:D31) -> 875.17185 | E37: =SUMPRODUCT(E14:E20,E25:E31) -> 574.87878 | F37: =SUMPRODUCT(F14:F20,F25:F31) -> 726.27698 | G37: =SUMPRODUCT(G14:G20,G25:G31) -> 611.73678 | H37: =SUMPRODUCT(H14:H20,H25:H31) -> 1699.8361 | I37: =SUMPRODUCT(I14:I20,I25:I31) -> 271.29687 | M37: kg-out/kg-in | N37: Process | O37: P1 | P37: P2 | Q37: P3 | R37: P4 | S37: P5 | T37: P6 | U37: P7 | V37: P8
A38: Aggregate yield% | B38: =B37/B36 -> 0.90650004 | C38: =C37/C36 -> 0.87432486 | D38: =D37/D36 -> 0.82770805 | E38: =E37/E36 -> 0.88530035 | F38: =F37/F36 -> 0.92509491 | G38: =G37/G36 -> 0.90632946 | H38: =H37/H36 -> 0.84217824 | I38: =I37/I36 -> 0.9718051 | N38: F1 | O38: =O14*O26 -> 0.3245564 | P38: =P14*P26 -> 0.23774471 | Q38: =Q14*Q26 -> 0.29791523 | R38: =R14*R26 -> 0.37554957 | S38: =S14*S26 -> 0.13374608 | T38: =T14*T26 -> 0.2641674 | U38: =U14*U26 -> 0.84198687 | V38: =V14*V26 -> 0.07296682
N39: F2 | O39: =O15*O27 -> 0.562284 | P39: =P15*P27 -> 0.096481465 | Q39: =Q15*Q27 -> 0.30906322 | R39: =R15*R27 -> 0.28017436 | S39: =S15*S27 -> 0.23124641 | T39: =T15*T27 -> 0.26840306 | U39: =U15*U27 -> 0 | V39: =V15*V27 -> 0.10930867
A40: This section is for estimating fabricating yield efficiencies, not for presenting product fabrication (refer to "Display") | N40: F3 | O40: =O16*O28 -> 0.0083566623 | P40: =P16*P28 -> 0.00075969658 | Q40: =Q16*Q28 -> 0.0051145214 | R40: =R16*R28 -> 0.0029742501 | S40: =S16*S28 -> 0.44625637 | T40: =T16*T28 -> 0.0080120318 | U40: =U16*U28 -> 0.00019137716 | V40: =V16*V28 -> 0.0069182703
N41: F4 | O41: =O17*O29 -> 0 | P41: =P17*P29 -> 0.013864463 | Q41: =Q17*Q29 -> 0.051510537 | R41: =R17*R29 -> 0.0107073 | S41: =S17*S29 -> 0.00049201363 | T41: =T17*T29 -> 0.0057228798 | U41: =U17*U29 -> 0 | V41: =V17*V29 -> 0.15670159
A42: Table S11 Scrap originated from | B42: =B2 -> Construction | C42: =C2 -> Trans. Auto | D42: =D2 -> Trans. Other | E42: =E2 -> Durables | F42: =F2 -> Electrical | G42: =G2 -> Machinery | H42: =H2 -> Container | I42: =I2 -> Other | N42: SC1 | O42: =O18*O30 -> 0.0056527231 | P42: =P18*P30 -> 0.26279452 | Q42: =Q18*Q30 -> 0.08207015 | R42: =R18*R30 -> 0.10797096 | S42: =S18*S30 -> 0.056689371 | T42: =T18*T30 -> 0.18005127 | U42: =U18*U30 -> 0 | V42: =V18*V30 -> 0.31302308
...

Sheet end_use
A1: idx | B1: category | C1: life | D1: std | E1: collect_rate | F1: recyclable | G1: recyc_rate | H1: Available | I1: Collected | J1: semi_DtD | K1: semi_import | L1: semi_inflow | M1: dom_fabricated | N1: import | O1: export | P1: dom_consumed | Q1: efficiency | R1: lambda | S1: Growth/year | T1: color
A2: P1 | B2: B&C | C2: 70 | D2: 23 | E2: 0.95 | F2: 1 | G2: =I2/H2 -> 0.95 | H2: 262.24073 | I2: =H2*E2 -> 249.12869 | J2: =Raw!P24 -> 1119.6016 | K2: =L2-J2 -> 174.64875 | L2: {=TRANSPOSE(Raw!P42:W42)} -> 1294.2504 | M2: =L2*Q2 -> 1173.238 | N2: 286.68855 | O2: 38.769757 | P2: =M2+N2-O2 -> 1421.1568 | Q2: {=TRANSPOSE(downstream!O33:V33)} -> 0.90650004 | R2: =S2/P2 -> -0.0054832298 | S2: -7.7925293 | T2: slateblue
A3: P2 | B3: Auto | C3: 16 | D3: 5 | E3: 0.95 | F3: 1 | G3: =I3/H3 -> 0.95 | H3: 1413.8677 | I3: =H3*E3 -> 1343.1743 | J3: =Raw!Q24 -> 1759.374 | K3: =L3-J3 -> 274.44804 | L3: 2033.822 | M3: =L3*Q3 -> 1778.2212 | N3: 477.63228 | O3: 580.23903 | P3: =M3+N3-O3 -> 1675.6144 | Q3: 0.87432486 | R3: =S3/P3 -> 0.017890499 | S3: 29.977578 | T3: blue
A4: P3 | B4: Transp. | C4: 35 | D4: 10 | E4: 0.95 | F4: 1 | G4: =I4/H4 -> 0.95 | H4: 524.78957 | I4: =H4*E4 -> 498.55009 | J4: =Raw!R24 -> 914.66356 | K4: =L4-J4 -> 142.68008 | L4: 1057.3436 | M4: =L4*Q4 -> 875.17185 | N4: 203.78376 | O4: 186.99253 | P4: =M4+N4-O4 -> 891.96308 | Q4: 0.82770805 | R4: =S4/P4 -> 0.019421496 | S4: 17.323257 | T4: navy
A5: P4 | B5: Cons. Dur. | C5: 20 | D5: 6 | E5: 0.95 | F5: 1 | G5: =I5/H5 -> 0.95 | H5: 885.04114 | I5: =H5*E5 -> 840.78908 | J5: =Raw!S24 -> 561.73419 | K5: =L5-J5 -> 87.625968 | L5: 649.36016 | M5: =L5*Q5 -> 574.87878 | N5: 975.85845 | O5: 126.03786 | P5: =M5+N5-O5 -> 1424.6994 | Q5: 0.88530035 | R5: =S5/P5 -> 0.014834749 | S5: 21.135057 | T5: skyblue
A6: P5 | B6: Electrical | C6: 50 | D6: 16 | E6: 0.95 | F6: 1 | G6: =I6/H6 -> 0.95 | H6: 348.47076 | I6: =H6*E6 -> 331.04723 | J6: =Raw!T24 -> 679.14297 | K6: =L6-J6 -> 105.94078 | L6: 785.08375 | M6: =L6*Q6 -> 726.27698 | N6: 406.9013 | O6: 205.8587 | P6: =M6+N6-O6 -> 927.31958 | Q6: 0.92509491 | R6: =S6/P6 -> 0.018814211 | S6: 17.446786 | T6: blueviolet
A7: P6 | B7: M&E | C7: 40 | D7: 13 | E7: 0.95 | F7: 1 | G7: =I7/H7 -> 0.95 | H7: 264.14836 | I7: =H7*E7 -> 250.94094 | J7: =Raw!U24 -> 583.88016 | K7: =L7-J7 -> 91.080559 | L7: 674.96072 | M7: =L7*Q7 -> 611.73678 | N7: 194.71806 | O7: 97.259921 | P7: =M7+N7-O7 -> 709.19492 | Q7: 0.90632946 | R7: =S7/P7 -> 0.019298416 | S7: 13.686339 | T7: steelblue
A8: P7 | B8: Cont. & Pack. | C8: 1 | D8: 0 | E8: 0.366 | F8: 1 | G8: =I8/H8 -> 0.366 | H8: 1699.8356 | I8: =H8*E8 -> 622.13984 | J8: =Raw!V24 -> 1746.0161 | K8: =L8-J8 -> 272.36432 | L8: 2018.3804 | M8: =L8*Q8 -> 1699.8361 | N8: 0 | O8: 0 | P8: =M8+N8-O8 -> 1699.8361 | Q8: 0.84217824 | R8: =S8/P8 -> 3.3747386e-06 | S8: 0.0057365025 | T8: royalblue
A9: P8 | B9: Other | C9: 35 | D9: 10 | E9: 0.95 | F9: 1 | G9: =I9/H9 -> 0.95 | H9: 261.68704 | I9: =H9*E9 -> 248.60269 | J9: =Raw!W24 -> 241.49649 | K9: =L9-J9 -> 37.67149 | L9: 279.16798 | M9: =L9*Q9 -> 271.29687 | N9: 0 | O9: 0 | P9: =M9+N9-O9 -> 271.29687 | Q9: 0.9718051 | R9: =S9/P9 -> -0.0058497826 | S9: -1.5870277 | T9: slategrey
H10: =SUM(H2:H9) -> 5660.0809 | I10: =SUM(I2:I9) -> 4384.3729 | J10: =SUM(J2:J9) -> 7605.9091 | K10: =SUM(K2:K9) -> 1186.46 | L10: =SUM(L2:L9) -> 8792.3691 | M10: =SUM(M2:M9) -> 7710.6565 | N10: =SUM(N2:N9) -> 2545.5824 | O10: =SUM(O2:O9) -> 1235.1578 | P10: =SUM(P2:P9) -> 9021.0811
L11: =J10+K10 -> 8792.3691 | R11: Average growth rate
R12: =SUMPRODUCT(P2:P9,R2:R9)/P10 -> 0.0099982691
R13: Average age
R14: =SUMPRODUCT(C2:C9,P2:P9)/P10 -> 30.144115

Sheet Process
A1: Label | B1: Process | C1: Stage | D1: Output | E1: CF Ref | F1: Input | G1: CF_Import | H1: Display | I1: MJ_per_kg | J1: NG_ratio | K1: ele_ratio | L1: clean_grid_ratio | M1: CO2_per_MJ | N1: CF_energy | O1: CF_process | P1: CF (kgCO2/kg-in) | Q1: Efficiency | R1: waste_per_value | S1: CF (kgCO2/kg-out)
A2: M | B2: Bayer Process | C2: Source | D2: Alumina | E2: 1.447 | F2: Bauxite | G2: 0.045 | H2: Alumina | I2: 15.81 | J2: 0.97 | K2: =1-J2 -> 0.03 | L2: =$J$30 -> 0.40353852 | M2: =J2*I$28+K2*(1-L2)*I$29+K2*L2*I$30 -> 0.070596468 | N2: =I2*M2 -> 1.1161302 | O2: 0.331 | P2: =N2+O2 -> 1.4471302 | Q2: =Raw!AD2 -> 0.94791722 | R2: =Raw!AA2/SUM(Raw!$X$24:$Z$24) -> 0.0034482831 | S2: =P2/Q2 -> 1.5266419
A3: EoL | B3: EoL Scrap Processing | C3: Source | D3: Scrap | E3: 0 | F3: Scrap | G3: 0 | H3: External Scrap | I3: =I5/10 -> 0.597265 | J3: 0 | K3: =1-J3 -> 1 | L3: =$J$30 -> 0.40353852 | M3: =J3*I$28+K3*(1-L3)*I$29+K3*L3*I$30 -> 0.12221559 | N3: =I3*M3 -> 0.072995097 | O3: 0 | P3: =N3+O3 -> 0.072995097 | Q3: =Raw!AD3 -> 1 | R3: =Raw!AA3/SUM(Raw!$X$24:$Z$24) -> 0 | S3: =P3/Q3 -> 0.072995097
A4: E | B4: Electrolysis | C4: Processing | D4: Aluminum_primary | E4: =I35 -> 5.4091196 | F4: Alumina | G4: 3.827 | H4: Primary Metal | I4: 53.85 | J4: 0 | K4: =1-J4 -> 1 | L4: =I41 -> 0.68215492 | M4: =J4*I$28+K4*(1-L4)*I$29+K4*L4*I$30 -> 0.067981392 | N4: =I4*M4 -> 3.6607979 | O4: =E4-N4 -> 1.7483216 | P4: =N4+O4 -> 5.4091196 | Q4: =Raw!AD4 -> 0.98533588 | R4: =Raw!AA4/SUM(Raw!$X$24:$Z$24) -> 0.0013706771 | S4: =P4/Q4 -> 5.48962
A5: R1 | B5: Remelting | C5: Processing | D5: Aluminum_secondary | E5: =I47*Q5 -> 0.3905355 | F5: Primary Metal | G5: 10.845 | H5: Remelted Metal | I5: =6.287*upstream!Y20 -> 5.97265 | J5: 0.923 | K5: =1-J5 -> 0.077 | L5: =$J$30 -> 0.40353852 | M5: =J5*I$28+K5*(1-L5)*I$29+K5*L5*I$30 -> 0.073097601 | N5: =I5*M5 -> 0.43658639 | O5: 0 | P5: =N5+O5 -> 0.43658639 | Q5: =Raw!AD5 -> 0.95 | R5: =Raw!AA5/SUM(Raw!$X$24:$Z$24) -> 0.031062338 | S5: =P5/Q5 -> 0.45956462
A6: R2 | B6: Refining | C6: Processing | D6: Aluminum_secondary | E6: =I47*Q6 -> 0.3905355 | F6: Primary Metal | G6: =G5 -> 10.845 | H6: Recycled Metal | I6: =6.287*upstream!Y32 -> 5.97265 | J6: 0.923 | K6: =1-J6 -> 0.077 | L6: =$J$30 -> 0.40353852 | M6: =J6*I$28+K6*(1-L6)*I$29+K6*L6*I$30 -> 0.073097601 | N6: =I6*M6 -> 0.43658639 | O6: 0 | P6: =N6+O6 -> 0.43658639 | Q6: =Raw!AD6 -> 0.95 | R6: =Raw!AA6/SUM(Raw!$X$24:$Z$24) -> 0.0095771525 | S6: =P6/Q6 -> 0.45956462
A7: C1 | B7: Wrought Ingot Casting | C7: Casting | D7: Wrought_ingot | E7: =I46*Q7 -> 0.11562 | F7: Primary Metal | G7: =G5 -> 10.845 | H7: Wrought Alloys | I7: 1.18 | J7: =0.839 -> 0.839 | K7: =1-J7 -> 0.161 | L7: =$J$30 -> 0.40353852 | M7: =J7*I$28+K7*(1-L7)*I$29+K7*L7*I$30 -> 0.077567711 | N7: =I7*M7 -> 0.091529899 | O7: 0 | P7: =N7+O7 -> 0.091529899 | Q7: =Raw!AD7 -> 1 | R7: =Raw!AA7/SUM(Raw!$X$24:$Z$24) -> 0 | S7: =P7/Q7 -> 0.091529899
A8: C2 | B8: Foundry Ingot Casting | C8: Casting | D8: Cast_ingot | E8: =I46*Q8 -> 0.11562 | F8: Primary Metal | G8: =G5 -> 10.845 | H8: Foundry Alloys | I8: 1.18 | J8: =0.839 -> 0.839 | K8: =1-J8 -> 0.161 | L8: =$J$30 -> 0.40353852 | M8: =J8*I$28+K8*(1-L8)*I$29+K8*L8*I$30 -> 0.077567711 | N8: =I8*M8 -> 0.091529899 | O8: 0 | P8: =N8+O8 -> 0.091529899 | Q8: =Raw!AD8 -> 1 | R8: =Raw!AA8/SUM(Raw!$X$24:$Z$24) -> 0 | S8: =P8/Q8 -> 0.091529899
A9: F1 | B9: Rolling | C9: Forming | D9: Sheets | E9: 0.41 | F9: Wrought Alloys | G9: 4.076 | H9: Sheets and Foils | I9: =4.245 -> 4.245 | J9: 0.482 | K9: =1-J9 -> 0.518 | L9: =$J$30 -> 0.40353852 | M9: =J9*I$28+K9*(1-L9)*I$29+K9*L9*I$30 -> 0.096565678 | N9: =I9*M9 -> 0.4099213 | O9: 0 | P9: =N9+O9 -> 0.4099213 | Q9: =Raw!AD9 -> 0.70768 | R9: =Raw!AA9/SUM(Raw!$X$24:$Z$24) -> 0 | S9: =P9/Q9 -> 0.5792467
A10: F2 | B10: Extrusion | C10: Forming | D10: Extrusions | E10: 0.555 | F10: =F9 -> Wrought Alloys | G10: =G9 -> 4.076 | H10: Extrusions | I10: 5.899 | J10: =0.527 -> 0.527 | K10: =1-J10 -> 0.473 | L10: =$J$30 -> 0.40353852 | M10: =J10*I$28+K10*(1-L10)*I$29+K10*L10*I$30 -> 0.094170976 | N10: =I10*M10 -> 0.55551459 | O10: 0 | P10: =N10+O10 -> 0.55551459 | Q10: =Raw!AD10 -> 0.73855 | R10: =Raw!AA10/SUM(Raw!$X$24:$Z$24) -> 0 | S10: =P10/Q10 -> 0.75216924
A11: F3 | B11: Wire Drawing | C11: Forming | D11: Cables | E11: =E10 -> 0.555 | F11: =F9 -> Wrought Alloys | G11: =G9 -> 4.076 | H11: Cables/Wires | I11: =I10 -> 5.899 | J11: =J10 -> 0.527 | K11: =1-J11 -> 0.473 | L11: =$J$30 -> 0.40353852 | M11: =J11*I$28+K11*(1-L11)*I$29+K11*L11*I$30 -> 0.094170976 | N11: =I11*M11 -> 0.55551459 | O11: 0 | P11: =N11+O11 -> 0.55551459 | Q11: =Raw!AD11 -> 0.73855 | R11: =Raw!AA11/SUM(Raw!$X$24:$Z$24) -> 0 | S11: =P11/Q11 -> 0.75216924
A12: F4 | B12: Forging and Powdering | C12: Forming | D12: Forgings | E12: =E9 -> 0.41 | F12: =F9 -> Wrought Alloys | G12: =G9 -> 4.076 | H12: Forgings and Powders | I12: =I9 -> 4.245 | J12: =J9 -> 0.482 | K12: =1-J12 -> 0.518 | L12: =$J$30 -> 0.40353852 | M12: =J12*I$28+K12*(1-L12)*I$29+K12*L12*I$30 -> 0.096565678 | N12: =I12*M12 -> 0.4099213 | O12: 0 | P12: =N12+O12 -> 0.4099213 | Q12: =Raw!AD12 -> 0.8 | R12: =Raw!AA12/SUM(Raw!$X$24:$Z$24) -> 0 | S12: =P12/Q12 -> 0.51240163
A13: SC1 | B13: Die Casting | C13: Forming | D13: Castings | E13: =677.23/1000 -> 0.67723 | F13: Foundry Alloys | G13: 2.29 | H13: Die Castings | I13: =5.16 -> 5.16 | J13: 0.648 | K13: =1-J13 -> 0.352 | L13: =$J$30 -> 0.40353852 | M13: =J13*I$28+K13*(1-L13)*I$29+K13*L13*I$30 -> 0.087731889 | N13: =I13*M13 -> 0.45269655 | O13: 0 | P13: =N13+O13 -> 0.45269655 | Q13: =Raw!AE13/Raw!AC13 -> 0.95684803 | R13: =Raw!AA13/SUM(Raw!$X$24:$Z$24) -> 0.0044894603 | S13: =P13/Q13 -> 0.47311228
A14: SC2 | B14: Permanent Mold Casting | C14: Forming | D14: Castings | E14: =E13 -> 0.67723 | F14: =F13 -> Foundry Alloys | G14: =G13 -> 2.29 | H14: Permanent Mold Castings | I14: =I13 -> 5.16 | J14: 0.648 | K14: =1-J14 -> 0.352 | L14: =$J$30 -> 0.40353852 | M14: =J14*I$28+K14*(1-L14)*I$29+K14*L14*I$30 -> 0.087731889 | N14: =I14*M14 -> 0.45269655 | O14: 0 | P14: =N14+O14 -> 0.45269655 | Q14: =Raw!AE14/Raw!AC14 -> 0.95684803 | R14: =Raw!AA14/SUM(Raw!$X$24:$Z$24) -> 0.0030789967 | S14: =P14/Q14 -> 0.47311228
A15: SC3 | B15: Sand Casting | C15: Forming | D15: Castings | E15: =E13 -> 0.67723 | F15: =F13 -> Foundry Alloys | G15: =G13 -> 2.29 | H15: Sand Castings | I15: =I13 -> 5.16 | J15: 0.648 | K15: =1-J15 -> 0.352 | L15: =$J$30 -> 0.40353852 | M15: =J15*I$28+K15*(1-L15)*I$29+K15*L15*I$30 -> 0.087731889 | N15: =I15*M15 -> 0.45269655 | O15: 0 | P15: =N15+O15 -> 0.45269655 | Q15: =Raw!AE15/Raw!AC15 -> 0.95684803 | R15: =Raw!AA15/SUM(Raw!$X$24:$Z$24) -> 0.0014085072 | S15: =P15/Q15 -> 0.47311228
