Workbook

Sheet Mining and Bayer
A1: Process | B1: Bauxite mining | M1: Domestic alumina production | O1: #M | X1: Global alumina production
A2: Report unit | B2: 1000 kg bauxite | M2: 1000 kg total alumina | X2: 1000 kg total alumina
A3: Scaling factor | B3: 1 | M3: 0.455 and add to scaled global alumina production | X3: 0.555 and add to scaled domestic alumina production
B4: Inputs | M4: Inputs | X4: Inputs
B5: Parameter | C5: Flows | D5: Quantities | E5: Amount | F5: Factor | G5: Units | H5: Tracked flows | I5: Standard deviation | J5: Origin | K5: Comment | M5: Parameter | N5: Flows | O5: Quantities | P5: Amount | Q5: Factor | R5: Units | S5: Tracked flows | T5: Standard deviation | U5: Origin | V5: Comment | X5: Parameter | Y5: Flows | Z5: Quantities | AA5: Amount | AB5: Factor | AC5: Units | AD5: Tracked flows | AE5: Standard deviation | AF5: Origin | AG5: Comment
C6: Electricity [Electric power] | D6: Energy (net calorific value) | E6: 5.364 | F6: 5.364 | G6: MJ | H6: X | I6: 0 | J6: (No statement) | K6: x | N6: Bauxite [Inorganic intermediate products] | O6: Mass | P6: 2234 | Q6: 2234 | R6: kg | S6: X | T6: 0 | U6: Estimated | V6: x | Y6: Bauxite [Inorganic intermediate products] | Z6: Mass | AA6: 2847 | AB6: 2847 | AC6: kg | AD6: X | AE6: 0 | AF6: Estimated | AG6: x
C7: Thermal energy from heavy fuel oil (MJ) [Thermal energy] | D7: Energy (net calorific value) | E7: 20.0178 | F7: 20.0178 | G7: MJ | H7: X | I7: 0 | J7: (No statement) | K7: =.495 kg | N7: Electricity [Electric power] | O7: Energy (net calorific value) | P7: 268.2 | Q7: 268.2 | R7: MJ | S7: X | T7: 0 | U7: (No statement) | V7: x | Y7: Electricity [Electric power] | Z7: Energy (net calorific value) | AA7: 784.8 | AB7: 784.8 | AC7: MJ | AD7: X | AE7: 0 | AF7: (No statement) | AG7: x
C8: Thermal energy from light fuel oil (MJ) [Thermal energy] | D8: Energy (net calorific value) | E8: 70.4544 | F8: 70.4544 | G8: MJ | H8: X | I8: 0 | J8: (No statement) | K8: =1.64 kg (diesel) | N8: Lime quicklime (lumpy) [Minerals] | O8: Mass | P8: 24.8 | Q8: 24.8 | R8: kg | S8: X | T8: 0 | U8: Estimated | V8: x | Y8: Lime quicklime (lumpy) [Minerals] | Z8: Mass | AA8: 31.5 | AB8: 31.5 | AC8: kg | AD8: X | AE8: 0 | AF8: Estimated | AG8: x
C9: Bauxite [Non renewable resources] | D9: Mass | E9: 1100 | F9: 1100 | G9: kg | I9: 0 | J9: (No statement) | K9: from 2005 data, assume 110% of output | N9: Sodium hydroxide (100%; caustic soda) [Inorganic intermediate products] | O9: Mass | P9: 55.6 | Q9: 55.6 | R9: kg | S9: X | T9: 0 | U9: Estimated | V9: x | Y9: Sodium hydroxide (100%; caustic soda) [Inorganic intermediate products] | Z9: Mass | AA9: 72.97 | AB9: 72.97 | AC9: kg | AD9: X | AE9: 0 | AF9: Estimated | AG9: x
C10: Fresh water [Water] | D10: Mass | E10: 481 | F10: 481 | G10: kg | I10: 0 | J10: (No statement) | K10: x | N10: Thermal energy from natural gas (MJ) [Thermal energy] | O10: Energy (net calorific value) | P10: 8562.4643 | Q10: 8562.4643 | R10: MJ | S10: X | T10: 0 | U10: Estimated | V10: x | Y10: Thermal energy (hard coal) [Thermal energy] | Z10: Energy (net calorific value) | AA10: 8149.1713 | AB10: 8149.1713 | AC10: MJ | AD10: X | AE10: 0 | AF10: (No statement) | AG10: x From hard coal
B11: Outputs | N11: Fresh water [Water] | O11: Mass | P11: 4470 | Q11: 4470 | R11: kg | T11: 0 | U11: Estimated | V11: x | Y11: Thermal energy from heavy fuel oil (MJ) [Thermal energy] | Z11: Energy (net calorific value) | AA11: 1027.176 | AB11: 1027.176 | AC11: MJ | AD11: X | AE11: 0 | AF11: Estimated | AG11: x
B12: Parameter | C12: Flows | D12: Quantities | E12: Amount | F12: Factor | G12: Units | H12: Tracked flows | I12: Standard deviation | J12: Origin | K12: Comment | N12: Rain water [Water] | O12: Mass | P12: 3856 | Q12: 3856 | R12: kg | T12: 0 | U12: (No statement) | Y12: Thermal energy from light fuel oil (MJ) [Thermal energy] | Z12: Energy (net calorific value) | AA12: 41.658312 | AB12: 41.658312 | AC12: MJ | AD12: X | AE12: 0 | AF12: (No statement) | AG12: x (diesel)
C13: Bauxite [Inorganic intermediate products] | D13: Mass | E13: 1000 | F13: 1000 | G13: kg | H13: X | I13: 0 | J13: (No statement) | N13: Sea water [Water] | O13: Mass | P13: 2442 | Q13: 2442 | R13: kg | T13: 0 | U13: (No statement) | V13: x | Y13: Thermal energy from natural gas (MJ) [Thermal energy] | Z13: Energy (net calorific value) | AA13: 2333.962 | AB13: 2333.962 | AC13: MJ | AD13: X | AE13: 0 | AF13: Estimated | AG13: x
C14: Non-hazardous waste for land-filling [Waste for disposal] | D14: Mass | E14: 0.0809 | F14: 0.0809 | G14: kg | H14: * | I14: 0 | J14: (No statement) | K14: x | M14: Outputs | Y14: Fresh water [Water] | Z14: Mass | AA14: 2033 | AB14: 2033 | AC14: kg | AE14: 0 | AF14: Estimated | AG14: x
C15: Dust (> PM10) [Particles to air] | D15: Mass | E15: 0.109 | F15: 0.109 | G15: kg | I15: 0 | J15: (No statement) | K15: x | M15: Parameter | N15: Flows | O15: Quantities | P15: Amount | Q15: Factor | R15: Units | S15: Tracked flows | T15: Standard deviation | U15: Origin | V15: Comment | Y15: Rain water [Water] | Z15: Mass | AA15: 476 | AB15: 476 | AC15: kg | AE15: 0 | AF15: (No statement)
C16: Overburden (deposited) [Stockpile goods] | D16: Mass | E16: 100 | F16: 100 | G16: kg | I16: 0 | J16: (No statement) | K16: from 2005 data, assumption based on input | N16: Aluminium oxide (alumina) [Inorganic intermediate products] | O16: Mass | P16: 1000 | Q16: 1000 | R16: kg | S16: X | T16: 0 | U16: Estimated | V16: x | Y16: Sea water [Water] | Z16: Mass | AA16: 193 | AB16: 193 | AC16: kg | AE16: 0 | AF16: (No statement) | AG16: x
C17: Processed water to lake [Other emissions to fresh water] | D17: Mass | E17: 28.1 | F17: 28.1 | G17: kg | I17: 0 | J17: (No statement) | K17: x | N17: Hazardous waste (unspec.) [Hazardous waste] | O17: Mass | P17: 1.93 | Q17: 1.93 | R17: kg | S17: * | T17: 0 | U17: (No statement) | V17: x | X17: Outputs
C18: Water vapour [Inorganic emissions to air] | D18: Mass | E18: 453 | F18: 453 | G18: kg | I18: 0 | J18: (No statement) | K18: x | N18: Red mud (wet) (3% NaOH) [Hazardous waste for disposal] | O18: Mass | P18: 1119 | Q18: 1119 | R18: kg | S18: * | T18: 0 | U18: Estimated | V18: Diff b/w bauxite in and alumina out | X18: Parameter | Y18: Flows | Z18: Quantities | AA18: Amount | AB18: Factor | AC18: Units | AD18: Tracked flows | AE18: Standard deviation | AF18: Origin | AG18: Comment
N19: Waste in landfill (inert material, sanitary and residual material landfill) [Consumer waste] | O19: Mass | P19: 0.23 | Q19: 0.23 | R19: kg | S19: * | T19: 0 | U19: (No statement) | V19: x | Y19: Aluminium oxide (imported) [Inorganic intermediate products] | Z19: Mass | AA19: 1000 | AB19: 1000 | AC19: kg | AD19: X | AE19: 0 | AF19: Estimated
E20: Input | F20: =F9/4 -> 275 | G20: kg Al | N20: Carbon dioxide [Inorganic emissions to air] | O20: Mass | P20: 185 | Q20: 185 | R20: kg | T20: 0 | U20: (No statement) | V20: non-fuel | Y20: Bauxite remnant [Waste for recovery] | Z20: Mass | AA20: 29.5 | AB20: 29.5 | AC20: kg | AD20: * | AE20: 0 | AF20: (No statement) | AG20: x
E21: Output | F21: =F13/4 -> 250 | G21: kg Al | N21: Cooling water to sea [Other emissions to sea water] | O21: Mass | P21: 2442 | Q21: 2442 | R21: kg | T21: 0 | U21: (No statement) | Y21: Hazardous waste (unspec.) [Hazardous waste] | Z21: Mass | AA21: 7.74 | AB21: 7.74 | AC21: kg | AD21: * | AE21: 0 | AF21: (No statement) | AG21: x
A22: Valuable inputs and outputs | E22: Efficiency | F22: =F21/F20 -> 0.90909091 | N22: Dust (> PM10) [Particles to air] | O22: Mass | P22: 0.249 | Q22: 0.249 | R22: kg | T22: 0 | U22: Estimated | V22: x | Y22: Red mud (wet) (3% NaOH) [Hazardous waste for disposal] | Z22: Mass | AA22: 1834 | AB22: 1834 | AC22: kg | AD22: * | AE22: 0 | AF22: Estimated | AG22: Diff b/w bauxite in and alumina out
A23: Energy consumption | N23: Mercury [Heavy metals to fresh water] | O23: Mass | P23: 5.94e-07 | Q23: 5.94e-07 | R23: kg | T23: 0 | U23: (No statement) | V23: x | Y23: Waste in landfill (inert material, sanitary and residual material landfill) [Consumer waste] | Z23: Mass | AA23: 11.3 | AB23: 11.3 | AC23: kg | AD23: * | AE23: 0 | AF23: (No statement) | AG23: x
A24: Dross, scrap, etc. | E24: NG | F24: =F7+F8 -> 90.4722 | G24: MJ | H24: =F24/F26 -> 0.9440295 | N24: Mercury [Heavy metals to air] | O24: Mass | P24: 6.74e-05 | Q24: 6.74e-05 | R24: kg | T24: 0 | U24: (No statement) | V24: x | Y24: Carbon dioxide [Inorganic emissions to air] | Z24: Mass | AA24: 237 | AB24: 237 | AC24: kg | AE24: 0 | AF24: (No statement) | AG24: non-fuel
A25: Process Emissions (Non Energy-related emissions) | E25: Electricity | F25: =F6 -> 5.364 | G25: MJ | H25: =F25/F26 -> 0.0559705 | N25: Nitrogen oxides [Inorganic emissions to air] | O25: Mass | P25: 0.592 | Q25: 0.592 | R25: kg | T25: 0 | U25: (No statement) | V25: x | Y25: Cooling water to sea [Other emissions to sea water] | Z25: Mass | AA25: 193 | AB25: 193 | AC25: kg | AE25: 0 | AF25: (No statement)
E26: Energy | F26: =SUM(F24:F25) -> 95.8362 | G26: MJ | N26: Oil (unspecified) [Hydrocarbons to fresh water] | O26: Mass | P26: 7.31 | Q26: 7.31 | R26: kg | T26: 0 | U26: (No statement) | V26: x | Y26: Dust (> PM10) [Particles to air] | Z26: Mass | AA26: 0.3469 | AB26: 0.3469 | AC26: kg | AE26: 0 | AF26: (No statement) | AG26: x (diff from particulates and M2.5, 2.5-10)
N27: Processed water to lake, regionalized, US [Other emissions to fresh water] | O27: Mass | P27: 4151 | Q27: 4151 | R27: kg | T27: 0 | U27: Estimated | Y27: Dust (PM2.5 - PM10) [Particles to air] | Z27: Mass | AA27: 0.0664 | AB27: 0.0664 | AC27: kg | AE27: 0 | AF27: Estimated | AG27: x
E28: MJ/kg-in | F28: =F26/F20 -> 0.34849527 | N28: Solids (suspended) [Particles to fresh water] | O28: Mass | P28: 0.0769 | Q28: 0.0769 | R28: kg | T28: 0 | U28: Estimated | V28: x | Y28: Dust (PM2.5) [Particles to air] | Z28: Mass | AA28: 0.0587 | AB28: 0.0587 | AC28: kg | AE28: 0 | AF28: (No statement) | AG28: x
E29: MJ/kg-out | F29: =F26/F21 -> 0.3833448 | G29: per kg Bauxite import (in Al content) | N29: Sulphur dioxide [Inorganic emissions to air] | O29: Mass | P29: 0.0612 | Q29: 0.0612 | R29: kg | T29: 0 | U29: Estimated | V29: x | Y29: Mercury [Heavy metals to air] | Z29: Mass | AA29: 0.000119 | AB29: 0.000119 | AC29: kg | AE29: 0 | AF29: (No statement) | AG29: x
N30: Water vapour [Inorganic emissions to air] | O30: Mass | P30: 4174.88 | Q30: 4174.88 | R30: kg | T30: 0 | U30: (No statement) | Y30: Mercury [Heavy metals to fresh water] | Z30: Mass | AA30: 4.67e-07 | AB30: 4.67e-07 | AC30: kg | AE30: 0 | AF30: (No statement) | AG30: x
Y31: Nitrogen oxides [Inorganic emissions to air] | Z31: Mass | AA31: 0.612 | AB31: 0.612 | AC31: kg | AE31: 0 | AF31: (No statement) | AG31: x
Y32: Oil (unspecified) [Hydrocarbons to fresh water] | Z32: Mass | AA32: 1.68 | AB32: 1.68 | AC32: kg | AE32: 0 | AF32: (No statement) | AG32: x
P33: Input | Q33: =Q6/4 -> 558.5 | R33: kg Al | Y33: Processed water to lake, regionalized, US [Other emissions to fresh water] | Z33: Mass | AA33: 1873 | AB33: 1873 | AC33: kg | AE33: 0 | AF33: Estimated
P34: Output | Q34: =Q16/102*54 -> 529.41176 | R34: kg Al | Y34: Solids (suspended) [Particles to fresh water] | Z34: Mass | AA34: 0.0413 | AB34: 0.0413 | AC34: kg | AE34: 0 | AF34: Estimated | AG34: x
P35: Efficiency | Q35: =Q34/Q33 -> 0.94791722 | Y35: Sulphur dioxide [Inorganic emissions to air] | Z35: Mass | AA35: 1.14 | AB35: 1.14 | AC35: kg | AE35: 0 | AF35: Estimated | AG35: x
Y36: Water vapour [Inorganic emissions to air] | Z36: Mass | AA36: 636 | AB36: 636 | AC36: kg | AE36: 0 | AF36: (No statement)
P37: NG | Q37: =Q10 -> 8562.4643 | R37: MJ | S37: =Q37/Q39 -> 0.96962856
P38: Electricity | Q38: =Q7 -> 268.2 | R38: MJ | S38: =Q38/Q39 -> 0.030371441
P39: Energy | Q39: =SUM(Q37:Q38) -> 8830.6643 | R39: MJ | AA39: Input | AB39: =AB6/4 -> 711.75 | AC39: kg Al
AA40: Output | AB40: =AB19/102*54 -> 529.41176 | AC40: kg Al
...

Sheet Electrolysis
A1: Process | B1: Electrolysis | D1: #E | M1: Anode production
A2: Report unit | B2: 1000 kg primary aluminum | M2: 1000 kg anode
A3: Scaling factor | B3: 1 | M3: 1
B4: Inputs | M4: Inputs
B5: Parameter | C5: Flows | D5: Quantities | E5: Amount | F5: Factor | G5: Units | H5: Tracked flows | I5: Standard deviation | J5: Origin | K5: Comment | M5: Parameter | N5: Flows | O5: Quantities | P5: Amount | Q5: Factor | R5: Units | S5: Tracked flows | T5: Standard deviation | U5: Origin | V5: Comment
C6: Aluminium fluoride [Inorganic intermediate products] | D6: Mass | E6: 16.8 | F6: 16.8 | G6: kg | H6: X | I6: 0 | J6: Estimated | K6: x | N6: Coke (C carrier) [Organic intermediate products] | O6: Mass | P6: 654 | Q6: 654 | R6: kg | S6: X | T6: 0 | U6: Estimated | V6: x
C7: Aluminium oxide (alumina) [Inorganic intermediate products] | D7: Mass | E7: 1917 | F7: 1917 | G7: kg | H7: X | I7: 0 | J7: Estimated | K7: x | N7: Electricity [Electric power] | O7: Energy (net calorific value) | P7: 892.8 | Q7: 892.8 | R7: MJ | S7: X | T7: 0 | U7: Measured | V7: x
C8: Anode (C carrier) [Operating materials] | D8: Mass | E8: 420 | F8: 420 | G8: kg | H8: X | I8: 0 | J8: (No statement) | K8: x Anodes (net)/Soderberg Paste | N8: Hard coal pitch (C carrier) [Organic intermediate products] | O8: Mass | P8: 153 | Q8: 153 | R8: kg | S8: X | T8: 0 | U8: Measured | V8: x
C9: Cathode carbon [Operating materials] | D9: Mass | E9: 6 | F9: 6 | G9: kg | H9: X | I9: 0 | J9: Estimated | K9: x | N9: Refractory [Minerals] | O9: Mass | P9: 4.26 | Q9: 4.26 | R9: kg | S9: X | T9: 0 | U9: (No statement) | V9: x
C10: Electricity [Electric power] | D10: Energy (net calorific value) | E10: 54648 | F10: 54648 | G10: MJ | H10: X | I10: 0 | J10: Estimated | K10: x | N10: Thermal energy from heavy fuel oil (MJ) [Thermal energy] | O10: Energy (net calorific value) | P10: 687.48 | Q10: 687.48 | R10: MJ | S10: X | T10: 0 | U10: Measured | V10: x
C11: Refractory [Minerals] | D11: Mass | E11: 6.661 | F11: 6.661 | G11: kg | H11: X | I11: 0 | J11: (No statement) | K11: x | N11: Thermal energy from light fuel oil (MJ) [Thermal energy] | O11: Energy (net calorific value) | P11: 21.86664 | Q11: 21.86664 | R11: MJ | S11: X | T11: 0 | U11: (No statement) | V11: diesel
C12: Steel part [Metal parts] | D12: Mass | E12: 6.19 | F12: 6.19 | G12: kg | H12: X | I12: 0 | J12: (No statement) | K12: x | N12: Thermal energy from natural gas (MJ) [Thermal energy] | O12: Energy (net calorific value) | P12: 1633.0829 | Q12: 1633.0829 | R12: MJ | S12: X | T12: 0 | U12: Measured | V12: x
C13: Fresh water [Water] | D13: Mass | E13: 9120 | F13: 9120 | G13: kg | I13: 0 | J13: (No statement) | K13: x | N13: Anodes (used) [Waste for recovery] | O13: Mass | P13: 353 | Q13: 353 | R13: kg | S13: * | T13: 0 | U13: (No statement)
C14: Rain water [Water] | D14: Mass | E14: 3380 | F14: 3380 | G14: kg | I14: 0 | J14: (No statement) | N14: Fresh water [Water] | O14: Mass | P14: 4516 | Q14: 4516 | R14: kg | T14: 0 | U14: Measured | V14: inputs smaller than outputs
B15: Outputs | N15: Rain water [Water] | O15: Mass | P15: 1183 | Q15: 1183 | R15: kg | T15: 0 | U15: (No statement)
B16: Parameter | C16: Flows | D16: Quantities | E16: Amount | F16: Factor | G16: Units | H16: Tracked flows | I16: Standard deviation | J16: Origin | K16: Comment | M16: Outputs
C17: Aluminium (liquid metal; prebaked) [Metals] | D17: Mass | E17: 1000 | F17: 1000 | G17: kg | H17: X | I17: 0 | J17: Estimated | K17: x | M17: Parameter | N17: Flows | O17: Quantities | P17: Amount | Q17: Factor | R17: Units | S17: Tracked flows | T17: Standard deviation | U17: Origin | V17: Comment
C18: Aluminium oxide (alumina) [Waste for disposal] | D18: Mass | E18: 8.96 | F18: 8.96 | G18: kg | H18: * | I18: 0 | J18: (No statement) | K18: to landfill | N18: Anode (C carrier) [Operating materials] | O18: Mass | P18: 1000 | Q18: 1000 | R18: kg | S18: X | T18: 0 | U18: Measured
C19: Carbon (unspecified) [Hazardous waste] | D19: Mass | E19: 5.8 | F19: 5.8 | G19: kg | H19: * | I19: 0 | J19: Estimated | K19: Waste carbon or mix | N19: Carbon (unspecified) [Waste for recovery] | O19: Mass | P19: 14.515 | Q19: 14.515 | R19: kg | S19: * | T19: 0 | U19: Measured | V19: waste carbon (landfill)
C20: Refractory [Hazardous waste] | D20: Mass | E20: 9.8 | F20: 9.8 | G20: kg | H20: * | I20: 0 | J20: (No statement) | K20: x spent pot lining + refractory to landfill | N20: Hazardous waste (unspec.) [Hazardous waste] | O20: Mass | P20: 3.84 | Q20: 3.84 | R20: kg | S20: * | T20: 0 | U20: (No statement) | V20: x
C21: Refractory bricks [Waste for recovery] | D21: Mass | E21: 6.2 | F21: 6.2 | G21: kg | H21: * | I21: 0 | J21: (No statement) | K21: x Spent pot lining carbon + spent pot lining refractory + refractory | N21: Refractories [Waste for recovery] | O21: Mass | P21: 19.96 | Q21: 19.96 | R21: kg | S21: * | T21: 0 | U21: (No statement) | V21: x
A22: Valuable inputs and outputs | C22: Sludge [Hazardous waste] | D22: Mass | E22: 10.3 | F22: 10.3 | G22: kg | H22: * | I22: 0 | J22: Estimated | K22: x | N22: Refractory [Hazardous waste] | O22: Mass | P22: 4.45 | Q22: 4.45 | R22: kg | S22: * | T22: 0 | U22: (No statement) | V22: x
A23: Energy consumption | C23: Steel scrap (St) [Waste for recovery] | D23: Mass | E23: 6.19 | F23: 6.19 | G23: kg | H23: * | I23: 0 | J23: (No statement) | K23: = to input | N23: Steel scrap (St) [Waste for recovery] | O23: Mass | P23: 11.1 | Q23: 11.1 | R23: kg | S23: * | T23: 0 | U23: (No statement) | V23: x
A24: Dross, scrap, etc. | C24: Benzo{a}pyrene [Group PAH to air] | D24: Mass | E24: 6.32e-05 | F24: 6.32e-05 | G24: kg | I24: 0 | J24: Measured | K24: x | N24: Unspecified industrial waste [Consumer waste] | O24: Mass | P24: 3.21 | Q24: 3.21 | R24: kg | S24: * | T24: 0 | U24: (No statement) | V24: x Diff b/w solid indust. waste and haz waste
A25: Process Emissions (Non Energy-related emissions) | C25: Carbon dioxide [Inorganic emissions to air] | D25: Mass | E25: 1503 | F25: 1503 | G25: kg | I25: 0 | J25: Calculated | K25: x | N25: Waste for recovery (unspecific) [Waste for recovery] | O25: Mass | P25: 9.9 | Q25: 9.9 | R25: kg | S25: * | T25: 0 | U25: (No statement) | V25: x By-product (other)
C26: Dust (> PM10) [Particles to air] | D26: Mass | E26: 0.115 | F26: 0.115 | G26: kg | I26: 0 | J26: (No statement) | N26: Carbon dioxide [Inorganic emissions to air] | O26: Mass | P26: 236 | Q26: 236 | R26: kg | T26: 0 | U26: (No statement) | V26: x non fuel
C27: Dust (PM2.5 - PM10) [Particles to air] | D27: Mass | E27: 0.685 | F27: 0.685 | G27: kg | I27: 0 | J27: Measured | K27: x | N27: Dust (PM2.5 - PM10) [Particles to air] | O27: Mass | P27: 0.204 | Q27: 0.204 | R27: kg | T27: 0 | U27: Measured | V27: x Difference b/w particulates and PM<2.5
C28: Dust (PM2.5) [Particles to air] | D28: Mass | E28: 1.34 | F28: 1.34 | G28: kg | I28: 0 | J28: (No statement) | K28: x | N28: Dust (PM2.5) [Particles to air] | O28: Mass | P28: 0.103 | Q28: 0.103 | R28: kg | T28: 0 | U28: (No statement) | V28: x
C29: Fluoride [Inorganic emissions to air] | D29: Mass | E29: 0.364 | F29: 0.364 | G29: kg | I29: 0 | J29: (No statement) | K29: x | N29: Fluoride [Inorganic emissions to air] | O29: Mass | P29: 0.0157 | Q29: 0.0157 | R29: kg | T29: 0 | U29: Measured | V29: x
C30: Fluoride [Inorganic emissions to sea water] | D30: Mass | E30: 0.0457 | F30: 0.0457 | G30: kg | I30: 0 | J30: (No statement) | K30: x | N30: Hydrogen fluoride [Inorganic emissions to air] | O30: Mass | P30: 0.0117 | Q30: 0.0117 | R30: kg | T30: 0 | U30: (No statement) | V30: x (gaseous fluride)
C31: Hydrogen fluoride [Inorganic emissions to air] | D31: Mass | E31: 0.334 | F31: 0.334 | G31: kg | I31: 0 | J31: Measured | K31: x gaseous fluoride | N31: Nitrogen oxides [Inorganic emissions to air] | O31: Mass | P31: 0.346 | Q31: 0.346 | R31: kg | T31: 0 | U31: Measured | V31: x
C32: Nitrogen oxides [Inorganic emissions to air] | D32: Mass | E32: 0.155 | F32: 0.155 | G32: kg | I32: 0 | J32: Measured | K32: x | N32: Polycyclic aromatic hydrocarbons (PAH) [Group PAH to air] | O32: Mass | P32: 0.0288 | Q32: 0.0288 | R32: kg | T32: 0 | U32: Measured | V32: x
C33: Oil (unspecified) [Hydrocarbons to fresh water] | D33: Mass | E33: 0.00325 | F33: 0.00325 | G33: kg | I33: 0 | J33: (No statement) | K33: x | N33: Processed water to lake, regionalized, US [Other emissions to fresh water] | O33: Mass | P33: 4630 | Q33: 4630 | R33: kg | T33: 0 | U33: (No statement) | V33: x
C34: Polycyclic aromatic hydrocarbons (PAH) [Group PAH to air] | D34: Mass | E34: 0.0146 | F34: 0.0146 | G34: kg | I34: 0 | J34: Measured | K34: x | N34: Solids (suspended) [Particles to fresh water] | O34: Mass | P34: 0.0503 | Q34: 0.0503 | R34: kg | T34: 0 | U34: (No statement) | V34: x
C35: Polycyclic aromatic hydrocarbons (PAH, unspec.) [Hydrocarbons to fresh water] | D35: Mass | E35: 5.162e-05 | F35: 5.162e-05 | G35: kg | I35: 0 | J35: (No statement) | K35: x | N35: Sulphur dioxide [Inorganic emissions to air] | O35: Mass | P35: 3.16 | Q35: 3.16 | R35: kg | T35: 0 | U35: Measured | V35: x
C36: Processed water to lake, regionalized, US [Other emissions to fresh water] | D36: Mass | E36: 11100 | F36: 11100 | G36: kg | I36: 0 | J36: (No statement) | K36: x | N36: Water vapour [Inorganic emissions to air] | O36: Mass | P36: 1068 | Q36: 1068 | R36: kg | T36: 0 | U36: (No statement) | V36: x
C37: R 116 (hexafluoroethane) [Halogenated organic emissions to air] | D37: Mass | E37: 0.003299 | F37: 0.003299 | G37: kg | I37: 0 | J37: Estimated | K37: x
C38: Solids (suspended) [Particles to fresh water] | D38: Mass | E38: 0.0387 | F38: 0.0387 | G38: kg | I38: 0 | J38: (No statement) | K38: x
C39: Sulphur dioxide [Inorganic emissions to air] | D39: Mass | E39: 16.6 | F39: 16.6 | G39: kg | I39: 0 | J39: Measured | K39: x | P39: Input | Q39: =Q6+Q8+Q13 -> 1160 | R39: kg C
C40: Tetrafluoromethane [Halogenated organic emissions to air] | D40: Mass | E40: 0.0354 | F40: 0.0354 | G40: kg | I40: 0 | J40: Estimated | K40: x | P40: Output | Q40: =Q18 -> 1000 | R40: kg C
...

Sheet Recycling
A1: Process | B1: 100% recycled aluminum scrap processing, remelting and casting | D1: #R1 | E1: #R2 | L1: 95% recycled aluminum scrap processing, remelting and casting | V1: Dross & saltcake recycling
A2: Report unit | B2: 1000 kg recovered aluminum | L2: 1000 kg secondary aluminum | V2: 1000 kg recovered aluminum
A3: Scaling factor | B3: 1 | L3: 1 | V3: 1
B4: Inputs | L4: Inputs | V4: Inputs
B5: Parameter | C5: Flows | D5: Quantities | E5: Amount | F5: Factor | G5: Units | H5: Tracked flows | I5: Standard deviation | J5: Origin | L5: Parameter | M5: Flows | N5: Quantities | O5: Amount | P5: Factor | Q5: Units | R5: Tracked flows | S5: Standard deviation | T5: Origin | V5: Parameter | W5: Flows | X5: Quantities | Y5: Amount | Z5: Factor | AA5: Units | AB5: Tracked flows | AC5: Standard deviation | AD5: Origin
C6: Alloying elements [Metals] | D6: Mass | E6: 6.456087 | F6: 6.456087 | G6: kg | H6: X | I6: 0 | J6: (No statement) | M6: Alloying elements [Metals] | N6: Mass | O6: 6.456087 | P6: 6.456087 | Q6: kg | R6: X | S6: 0 | T6: (No statement) | W6: Argon [Inorganic intermediate products] | X6: Mass | Y6: 17.5405 | Z6: 17.5405 | AA6: kg | AB6: X | AC6: 0 | AD6: (No statement)
C7: Aluminum input [Metals] | D7: Mass | E7: 55.4905 | F7: 55.4905 | G7: kg | H7: X | I7: 0 | J7: (No statement) | M7: Aluminum input [Metals] | N7: Mass | O7: 55.4905 | P7: 55.4905 | Q7: kg | R7: X | S7: 0 | T7: (No statement) | W7: Concentrated dross and saltcake [Waste for recovery] | X7: Mass | Y7: 2689.7871 | Z7: 2689.7871 | AA7: kg | AB7: X | AC7: 0 | AD7: (No statement)
C8: Argon [Inorganic intermediate products] | D8: Mass | E8: 0.144127 | F8: 0.144127 | G8: kg | H8: X | I8: 0 | J8: (No statement) | M8: Argon [Inorganic intermediate products] | N8: Mass | O8: 0.144127 | P8: 0.144127 | Q8: kg | R8: X | S8: 0 | T8: (No statement) | W8: Cryolite [Inorganic intermediate products] | X8: Mass | Y8: 2.7505 | Z8: 2.7505 | AA8: kg | AB8: X | AC8: 0 | AD8: (No statement)
C9: Dross [Metals] | D9: Mass | E9: 48.401914 | F9: 48.401914 | G9: kg | H9: X | I9: 0 | J9: (No statement) | M9: Dross [Metals] | N9: Mass | O9: 48.401914 | P9: 48.401914 | Q9: kg | R9: X | S9: 0 | T9: (No statement) | W9: Electricity [Electric power] | X9: Energy (net calorific value) | Y9: 757.07928 | Z9: 757.07928 | AA9: MJ | AB9: X | AC9: 0 | AD9: (No statement)
C10: Electricity [Electric power] | D10: Energy (net calorific value) | E10: 487.03044 | F10: 487.03044 | G10: MJ | H10: X | I10: 0 | J10: (No statement) | M10: Electricity [Electric power] | N10: Energy (net calorific value) | O10: 487.03044 | P10: 487.03044 | Q10: MJ | R10: X | S10: 0 | T10: (No statement) | W10: Lime quicklime (lumpy) [Minerals] | X10: Mass | Y10: 15.9813 | Z10: 15.9813 | AA10: kg | AB10: X | AC10: 0 | AD10: (No statement)
C11: Filter media [Operating materials] | D11: Mass | E11: 0.00894284 | F11: 0.00894284 | G11: kg | H11: X | I11: 0 | J11: (No statement) | M11: Filter media [Operating materials] | N11: Mass | O11: 0.00894284 | P11: 0.00894284 | Q11: kg | R11: X | S11: 0 | T11: (No statement) | W11: Potassium chloride [Inorganic intermediate products] | X11: Mass | Y11: 52.8181 | Z11: 52.8181 | AA11: kg | AB11: X | AC11: 0 | AD11: (No statement)
C12: Hydraulic oil [Operating materials] | D12: Mass | E12: 0.013699 | F12: 0.013699 | G12: kg | H12: X | I12: 0 | J12: (No statement) | M12: Hydraulic oil [Operating materials] | N12: Mass | O12: 0.013699 | P12: 0.013699 | Q12: kg | R12: X | S12: 0 | T12: (No statement) | W12: Refractory [Minerals] | X12: Mass | Y12: 0.6258 | Z12: 0.6258 | AA12: kg | AB12: X | AC12: 0 | AD12: (No statement)
C13: Lime quicklime (lumpy) [Minerals] | D13: Mass | E13: 0.14706 | F13: 0.14706 | G13: kg | H13: X | I13: 0 | J13: (No statement) | M13: Lime quicklime (lumpy) [Minerals] | N13: Mass | O13: 0.14706 | P13: 0.14706 | Q13: kg | R13: X | S13: 0 | T13: (No statement) | W13: Sodium chloride (rock salt) [Inorganic intermediate products] | X13: Mass | Y13: 158.1632 | Z13: 158.1632 | AA13: kg | AB13: X | AC13: 0 | AD13: (No statement)
C14: Nitrogen gaseous [Inorganic intermediate products] | D14: Mass | E14: 0.254537 | F14: 0.254537 | G14: kg | H14: X | I14: 0 | J14: (No statement) | M14: Nitrogen gaseous [Inorganic intermediate products] | N14: Mass | O14: 0.254537 | P14: 0.254537 | Q14: kg | R14: X | S14: 0 | T14: (No statement) | W14: Thermal energy from natural gas (MJ) [Thermal energy] | X14: Energy (net calorific value) | Y14: 5929.4885 | Z14: 5929.4885 | AA14: MJ | AB14: X | AC14: 0 | AD14: (No statement)
C15: Potassium chloride [Inorganic intermediate products] | D15: Mass | E15: 3.79758 | F15: 3.79758 | G15: kg | H15: X | I15: 0 | J15: (No statement) | M15: Potassium chloride [Inorganic intermediate products] | N15: Mass | O15: 3.79758 | P15: 3.79758 | Q15: kg | R15: X | S15: 0 | T15: (No statement) | V15: Outputs
C16: Refractory [Minerals] | D16: Mass | E16: 0.0465384 | F16: 0.0465384 | G16: kg | H16: X | I16: 0 | J16: (No statement) | M16: Refractory [Minerals] | N16: Mass | O16: 0.0465384 | P16: 0.0465384 | Q16: kg | R16: X | S16: 0 | T16: (No statement) | V16: Parameter | W16: Flows | X16: Quantities | Y16: Amount | Z16: Factor | AA16: Units | AB16: Tracked flows | AC16: Standard deviation | AD16: Origin
C17: Sodium chloride (rock salt) [Inorganic intermediate products] | D17: Mass | E17: 14.835992 | F17: 14.835992 | G17: kg | H17: X | I17: 0 | J17: (No statement) | M17: Sodium chloride (rock salt) [Inorganic intermediate products] | N17: Mass | O17: 14.835992 | P17: 14.835992 | Q17: kg | R17: X | S17: 0 | T17: (No statement) | W17: Aluminium ingot (secondary) [Metals] | X17: Mass | Y17: 1000 | Z17: 1000 | AA17: kg | AB17: X | AC17: 0 | AD17: (No statement)
C18: Steel band (packaging) [Metals] | D18: Mass | E18: 0.0229051 | F18: 0.0229051 | G18: kg | H18: X | I18: 0 | J18: (No statement) | M18: Steel band (packaging) [Metals] | N18: Mass | O18: 0.0229051 | P18: 0.0229051 | Q18: kg | R18: X | S18: 0 | T18: (No statement) | W18: Aluminium oxide (alumina) [Waste for recovery] | X18: Mass | Y18: 103.6887 | Z18: 103.6887 | AA18: kg | AB18: * | AC18: 0 | AD18: (No statement)
C19: Thermal energy from diesel fuel (MJ) [Thermal energy] | D19: Energy (net calorific value) | E19: 10.23005 | F19: 10.23005 | G19: MJ | H19: X | I19: 0 | J19: (No statement) | M19: Thermal energy from diesel fuel (MJ) [Thermal energy] | N19: Energy (net calorific value) | O19: 10.23005 | P19: 10.23005 | Q19: MJ | R19: X | S19: 0 | T19: (No statement) | W19: Filter dust [Hazardous waste] | X19: Mass | Y19: 68.3085 | Z19: 68.3085 | AA19: kg | AB19: * | AC19: 0 | AD19: (No statement)
C20: Thermal energy from natural gas (MJ) [Thermal energy] | D20: Energy (net calorific value) | E20: 5300.3589 | F20: 5300.3589 | G20: MJ | H20: X | I20: 0 | J20: (No statement) | M20: Thermal energy from natural gas (MJ) [Thermal energy] | N20: Energy (net calorific value) | O20: 5300.3589 | P20: 5300.3589 | Q20: MJ | R20: X | S20: 0 | T20: (No statement) | W20: Refractory [Hazardous waste] | X20: Mass | Y20: 2.6051 | Z20: 2.6051 | AA20: kg | AB20: * | AC20: 0 | AD20: (No statement)
C21: Thermal energy from propane (MJ) [Thermal energy] | D21: Energy (net calorific value) | E21: 2.080335 | F21: 2.080335 | G21: MJ | H21: X | I21: 0 | J21: (No statement) | M21: Thermal energy from propane (MJ) [Thermal energy] | N21: Energy (net calorific value) | O21: 2.080335 | P21: 2.080335 | Q21: MJ | R21: X | S21: 0 | T21: (No statement) | W21: Saltcake [Waste for disposal] | X21: Mass | Y21: 1474.1173 | Z21: 1474.1173 | AA21: kg | AB21: * | AC21: 0 | AD21: (No statement)
A22: Valuable inputs and outputs | C22: Untreated comingled aluminum scrap [Metals] | D22: Mass | E22: 263.41661 | F22: 263.41661 | G22: kg | H22: X | I22: 0 | J22: (No statement) | M22: Untreated comingled aluminum scrap [Metals] | N22: Mass | O22: 263.41661 | P22: 263.41661 | Q22: kg | R22: X | S22: 0 | T22: (No statement) | W22: Used oil (without water) [Waste for recovery] | X22: Mass | Y22: 0.1461 | Z22: 0.1461 | AA22: kg | AB22: * | AC22: 0 | AD22: (No statement)
A23: Energy consumption | C23: Untreated post-consumer aluminum scrap [Metals] | D23: Mass | E23: 375.70427 | F23: 375.70427 | G23: kg | H23: X | I23: 0 | J23: (No statement) | M23: Untreated post-consumer aluminum scrap [Metals] | N23: Mass | O23: 375.70427 | P23: 375.70427 | Q23: kg | R23: X | S23: 0 | T23: (No statement) | W23: Dust (PM10) [Particles to air] | X23: Mass | Y23: 0.2421 | Z23: 0.2421 | AA23: kg | AC23: 0 | AD23: (No statement)
A24: Dross, scrap, etc. | C24: Untreated pre-consumer aluminum scrap [Metals] | D24: Mass | E24: 309.35075 | F24: 309.35075 | G24: kg | H24: X | I24: 0 | J24: (No statement) | M24: Untreated pre-consumer aluminum scrap [Metals] | N24: Mass | O24: 309.35075 | P24: 309.35075 | Q24: kg | R24: X | S24: 0 | T24: (No statement) | W24: Hydrogen chloride [Inorganic emissions to air] | X24: Mass | Y24: 0.07507 | Z24: 0.07507 | AA24: kg | AC24: 0 | AD24: (No statement)
C25: Water (tap water) [Operating materials] | D25: Mass | E25: 139.88811 | F25: 139.88811 | G25: kg | H25: X | I25: 0 | J25: (No statement) | M25: Water (tap water) [Operating materials] | N25: Mass | O25: 139.88811 | P25: 139.88811 | Q25: kg | R25: X | S25: 0 | T25: (No statement) | W25: Hydrogen fluoride [Inorganic emissions to air] | X25: Mass | Y25: 0.02046 | Z25: 0.02046 | AA25: kg | AC25: 0 | AD25: (No statement)
B26: Outputs | L26: Outputs | W26: Lead [Heavy metals to air] | X26: Mass | Y26: 5e-05 | Z26: 5e-05 | AA26: kg | AC26: 0 | AD26: (No statement)
B27: Parameter | C27: Flows | D27: Quantities | E27: Amount | F27: Factor | G27: Units | H27: Tracked flows | I27: Standard deviation | J27: Origin | L27: Parameter | M27: Flows | N27: Quantities | O27: Amount | P27: Factor | Q27: Units | R27: Tracked flows | S27: Standard deviation | T27: Origin | W27: Nitrogen dioxide [Inorganic emissions to air] | X27: Mass | Y27: 0.0242 | Z27: 0.0242 | AA27: kg | AC27: 0 | AD27: (No statement)
C28: Aluminium ingot (secondary) [Metals] | D28: Mass | E28: 1000 | F28: 1000 | G28: kg | H28: X | I28: 0 | J28: (No statement) | M28: Aluminium ingot (secondary) [Metals] | N28: Mass | O28: 1000 | P28: 1000 | Q28: kg | R28: X | S28: 0 | T28: (No statement) | W28: Sulphur dioxide [Inorganic emissions to air] | X28: Mass | Y28: 0.1441 | Z28: 0.1441 | AA28: kg | AC28: 0 | AD28: (No statement)
C29: Dross [Waste for recovery] | D29: Mass | E29: 0.357087 | F29: 0.357087 | G29: kg | H29: * | I29: 0 | J29: (No statement) | M29: Dross [Waste for recovery] | N29: Mass | O29: 0.357087 | P29: 0.357087 | Q29: kg | R29: * | S29: 0 | T29: (No statement) | W29: VOC (unspecified) [Organic emissions to air (group VOC)] | X29: Mass | Y29: 0.0798 | Z29: 0.0798 | AA29: kg | AC29: 0 | AD29: (No statement)
C30: Dross for internal recycling [Waste for recovery] | D30: Mass | E30: 54.695053 | F30: 54.695053 | G30: kg | H30: * | I30: 0 | J30: (No statement) | M30: Dross for internal recycling [Waste for recovery] | N30: Mass | O30: 54.695053 | P30: 54.695053 | Q30: kg | R30: * | S30: 0 | T30: (No statement)
C31: Filter dust [Hazardous waste] | D31: Mass | E31: 3.478562 | F31: 3.478562 | G31: kg | H31: * | I31: 0 | J31: (No statement) | M31: Filter dust [Hazardous waste] | N31: Mass | O31: 3.478562 | P31: 3.478562 | Q31: kg | R31: * | S31: 0 | T31: (No statement)
C32: Filter media [Waste for disposal] | D32: Mass | E32: 0.0311899 | F32: 0.0311899 | G32: kg | H32: * | I32: 0 | J32: (No statement) | M32: Filter media [Waste for disposal] | N32: Mass | O32: 0.0311899 | P32: 0.0311899 | Q32: kg | R32: * | S32: 0 | T32: (No statement) | Y32: Input upperbound | Z32: =Z7*0.8 -> 2151.8297 | AA32: kg Al
C33: Hazardous waste (unspec.) [Hazardous waste] | D33: Mass | E33: 0.0760584 | F33: 0.0760584 | G33: kg | H33: * | I33: 0 | J33: (No statement) | M33: Hazardous waste (unspec.) [Hazardous waste] | N33: Mass | O33: 0.0760584 | P33: 0.0760584 | Q33: kg | R33: * | S33: 0 | T33: (No statement) | Y33: Output | Z33: =Z17 -> 1000 | AA33: kg Al
C34: Refractory [Hazardous waste] | D34: Mass | E34: 0.313897 | F34: 0.313897 | G34: kg | H34: * | I34: 0 | J34: (No statement) | M34: Refractory [Hazardous waste] | N34: Mass | O34: 0.313897 | P34: 0.313897 | Q34: kg | R34: * | S34: 0 | T34: (No statement) | Y34: Efficiency lowerbound | Z34: =Z33/Z32 -> 0.4647208
C35: Saltcake [Waste for recovery] | D35: Mass | E35: 1.793484 | F35: 1.793484 | G35: kg | H35: * | I35: 0 | J35: (No statement) | M35: Saltcake [Waste for recovery] | N35: Mass | O35: 1.793484 | P35: 1.793484 | Q35: kg | R35: * | S35: 0 | T35: (No statement)
C36: Saltcake [Waste for disposal] | D36: Mass | E36: 0.0413989 | F36: 0.0413989 | G36: kg | H36: * | I36: 0 | J36: (No statement) | M36: Saltcake [Waste for disposal] | N36: Mass | O36: 0.0413989 | P36: 0.0413989 | Q36: kg | R36: * | S36: 0 | T36: (No statement) | Y36: NG | Z36: =Z14 -> 5929.4885 | AA36: MJ | AB36: =Z36/Z38 -> 0.8867761
C37: Unspecified industrial waste [Consumer waste] | D37: Mass | E37: 2.768662 | F37: 2.768662 | G37: kg | H37: * | I37: 0 | J37: (No statement) | M37: Unspecified industrial waste [Consumer waste] | N37: Mass | O37: 2.768662 | P37: 2.768662 | Q37: kg | R37: * | S37: 0 | T37: (No statement) | Y37: Electricity | Z37: =Z9 -> 757.07928 | AA37: MJ | AB37: =Z37/Z38 -> 0.1132239
C38: Water (waste water, untreated) [Production residues in life cycle] | D38: Mass | E38: 96.532768 | F38: 96.532768 | G38: kg | H38: * | I38: 0 | J38: (No statement) | M38: Water (waste water, untreated) [Production residues in life cycle] | N38: Mass | O38: 96.532768 | P38: 96.532768 | Q38: kg | R38: * | S38: 0 | T38: (No statement) | Y38: Energy | Z38: =SUM(Z36:Z37) -> 6686.5678 | AA38: MJ
C39: Aluminium [Inorganic emissions to fresh water] | D39: Mass | E39: 0.000801686 | F39: 0.000801686 | G39: kg | I39: 0 | J39: (No statement) | M39: Aluminium [Inorganic emissions to fresh water] | N39: Mass | O39: 0.000801686 | P39: 0.000801686 | Q39: kg | S39: 0 | T39: (No statement)
C40: Biological oxygen demand (BOD) [Analytical measures to fresh water] | D40: Mass | E40: 0.003900883 | F40: 0.003900883 | G40: kg | I40: 0 | J40: (No statement) | M40: Biological oxygen demand (BOD) [Analytical measures to fresh water] | N40: Mass | O40: 0.003900883 | P40: 0.003900883 | Q40: kg | S40: 0 | T40: (No statement) | Y40: MJ/kg-in | Z40: =Z38/Z32 -> 3.1073871
...

Sheet Casting
A1: Process | B1: Cast house | D1: #C1 | E1: #C2 | M1: Cast aluminum production (shape casting) | P1: #SC1#SC2#SC3
A2: Report unit | B2: 1000 kg primary aluminum ingot | M2: 1000 kg cast aluminum
A3: Scaling factor | B3: 1 | M3: 1
B4: Inputs | M4: Inputs
B5: Parameter | C5: Flows | D5: Quantities | E5: Amount | F5: Factor | G5: Units | H5: Tracked flows | I5: Standard deviation | J5: Origin | K5: Comment | M5: Parameter | N5: Flows | O5: Quantities | P5: Amount | Q5: Factor | R5: Units | S5: Tracked flows | T5: Standard deviation | U5: Origin
C6: Aluminium (liquid metal) [Metals] | D6: Mass | E6: 1000 | F6: 1000 | G6: kg | H6: X | I6: 0 | J6: Calculated | K6: x | N6: Aluminium ingot [Metals] | O6: Mass | P6: 1.045 | Q6: 1.045 | R6: kg | S6: X | T6: 0 | U6: Literature
C7: Electricity [Electric power] | D7: Energy (net calorific value) | E7: 190.8 | F7: 190.8 | G7: MJ | H7: X | I7: 0 | J7: Calculated | K7: x | N7: Electricity [Electric power] | O7: Energy (net calorific value) | P7: 3.492 | Q7: 3.492 | R7: MJ | S7: X | T7: 0 | U7: Literature
C8: Nitrogen gaseous [Inorganic intermediate products] | D8: Mass | E8: 0.22 | F8: 0.22 | G8: kg | H8: X | I8: 0 | J8: (No statement) | K8: 2010 value | N8: Thermal energy (MJ) [Thermal energy] | O8: Energy (net calorific value) | P8: 1.9 | Q8: 1.9 | R8: MJ | S8: X | T8: 0 | U8: Literature
C9: Thermal energy from light fuel oil (MJ) [Thermal energy] | D9: Energy (net calorific value) | E9: 128.88 | F9: 128.88 | G9: MJ | H9: X | I9: 0 | J9: Calculated | K9: x(diesel) | M9: Outputs
C10: Thermal energy from natural gas (MJ) [Thermal energy] | D10: Energy (net calorific value) | E10: 863.15165 | F10: 863.15165 | G10: MJ | H10: X | I10: 0 | J10: Calculated | K10: x | M10: Parameter | N10: Flows | O10: Quantities | P10: Amount | Q10: Factor | R10: Units | S10: Tracked flows | T10: Standard deviation | U10: Origin
C11: Fresh water [Water] | D11: Mass | E11: 1900 | F11: 1900 | G11: kg | I11: 0 | J11: Calculated | K11: input less than output | N11: Aluminium part [Metal parts] | O11: Mass | P11: 1 | Q11: 1 | R11: kg | S11: X | T11: 0 | U11: Literature
B12: Outputs | N12: Aluminium scrap [Waste for recovery] | O12: Mass | P12: 0.045 | Q12: 0.045 | R12: kg | S12: * | T12: 0 | U12: Literature
B13: Parameter | C13: Flows | D13: Quantities | E13: Amount | F13: Factor | G13: Units | H13: Tracked flows | I13: Standard deviation | J13: Origin | K13: Comment | N13: Dust (PM2.5 - PM10) [Particles to air] | O13: Mass | P13: 0.0003 | Q13: 0.0003 | R13: kg | T13: 0 | U13: Literature | V13: Table 12-7: Breakdown of LCIA Results for Die Cast Aluminum, Representing 1,000 kg of Aluminum Cast Products
C14: Aluminium DC cast ingot [Metals] | D14: Mass | E14: 1000 | F14: 1000 | G14: kg | H14: X | I14: 0 | J14: Estimated | K14: x
C15: Dross [Waste for recovery] | D15: Mass | E15: 14.56 | F15: 14.56 | G15: kg | H15: * | I15: 0 | J15: Estimated | K15: x
C16: Dross (Fines) [Hazardous waste for disposal] | D16: Mass | E16: 3.87 | F16: 3.87 | G16: kg | H16: * | I16: 0 | J16: Estimated | K16: Dross - landfillx | P16: input | Q16: =Q6 -> 1.045 | R16: kg Al | S16: Primary/kg-in | T16: =0.157/Q16 -> 0.15023923 | U16: /kg ingot
C17: Filter dust [Hazardous waste] | D17: Mass | E17: 0.29 | F17: 0.29 | G17: kg | H17: * | I17: 0 | J17: (No statement) | K17: Filter dust - landfillx | P17: output | Q17: =Q11 -> 1 | R17: kg Al | S17: Primary/kg-out | T17: =0.157/Q17 -> 0.157 | U17: /kg semi
C18: Hazardous waste (unspec.) [Hazardous waste] | D18: Mass | E18: 1.59 | F18: 1.59 | G18: kg | H18: * | I18: 0 | J18: (No statement) | K18: x | P18: Net efficiency | Q18: =Q17/Q16 -> 0.9569378
C19: Industrial waste for municipal disposal [Consumer waste] | D19: Mass | E19: 0.08 | F19: 0.08 | G19: kg | H19: * | I19: 0 | J19: (No statement) | K19: other waste x
C20: Refractory [Hazardous waste] | D20: Mass | E20: 0.29279 | F20: 0.29279 | G20: kg | H20: * | I20: 0 | J20: Estimated | K20: x Refractory waste - landfill | P20: NG | Q20: =Q7 -> 3.492 | R20: MJ | S20: =Q20/Q22 -> 0.64762611
C21: Refractory bricks [Waste for recovery] | D21: Mass | E21: 0.587 | F21: 0.587 | G21: kg | H21: * | I21: 0 | J21: (No statement) | K21: x waste for recovery | P21: Electricity | Q21: =Q8 -> 1.9 | R21: MJ | S21: =Q21/Q22 -> 0.35237389
A22: Valuable inputs and outputs | C22: Dust (PM2.5 - PM10) [Particles to air] | D22: Mass | E22: 0.064 | F22: 0.064 | G22: kg | I22: 0 | J22: Measured | K22: x reported 0.06 particulates (assumed2.5-10) | P22: Energy | Q22: =SUM(Q20:Q21) -> 5.392 | R22: MJ
A23: Energy consumption | C23: Hydrogen chloride [Inorganic emissions to air] | D23: Mass | E23: 0.0472 | F23: 0.0472 | G23: kg | I23: 0 | J23: (No statement) | K23: x
A24: Dross, scrap, etc. | C24: Nitrogen oxides [Inorganic emissions to air] | D24: Mass | E24: 0.0876 | F24: 0.0876 | G24: kg | I24: 0 | J24: Measured | K24: x | P24: MJ/kg-in | Q24: =Q22/Q16 -> 5.1598086
C25: Polychlorinated dibenzo-p-dioxins (2,3,7,8 - TCDD) [Halogenated organic emissions to air] | D25: Mass | E25: 1.317e-09 | F25: 1.317e-09 | G25: kg | I25: 0 | J25: (No statement) | K25: x | P25: Mj/kg-out | Q25: =Q22/Q17 -> 5.392
C26: Processed water to lake, regionalized, US [Other emissions to fresh water] | D26: Mass | E26: 1444 | F26: 1444 | G26: kg | I26: 0 | J26: (No statement) | K26: x
C27: Sulphur dioxide [Inorganic emissions to air] | D27: Mass | E27: 0.0114 | F27: 0.0114 | G27: kg | I27: 0 | J27: Measured | K27: x | N27: Internal recovery rate | O27: 0.8
C28: Water vapour [Inorganic emissions to air] | D28: Mass | E28: 459 | F28: 459 | G28: kg | I28: 0 | J28: (No statement) | N28: Nominal efficiency eta` | O28: =(Q18-Q18*O27)/(1-Q18*O27) -> 0.81632653
E31: Input | F31: =F6 -> 1000 | G31: kg Al | H31: Dross recovery % | I31: =E15/(E15+E16) -> 0.79001628
E32: Output | F32: =F14 -> 1000 | G32: kg Al
E33: Efficiency | F33: =F32/F31 -> 1
E34: Source (p) | F34: MJ-Del/1000 kg Metal | G34: MJ-del/kg-in | H34: w_i^p
E35: NG | F35: =SUM(F9:F10) -> 992.03165 | G35: =F35/F6 -> 0.99203165 | H35: =F35/F37 -> 0.83869218 | I35: =H35 -> 0.83869218
E36: Electricity | F36: =F7 -> 190.8 | G36: =F36/F6 -> 0.1908 | H36: =F36/F37 -> 0.16130782 | I36: =H36 -> 0.16130782
E37: Energy | F37: =SUM(F35:F36) -> 1182.8316 | G37: =F37/F6 -> 1.1828316 | H37: =SUM(H35:H36) -> 1
E39: MJ/kg-in | F39: =F37/F31 -> 1.1828316
E40: MJ/kg-out | F40: =F37/F32 -> 1.1828316

Sheet Rolling (F1)
A1: Process | B1: Aluminum sheet production (remelting & casting, hot rolling & cold rolling) | N1: Aluminum automotive sheet production (remelting & casting, hot rolling & cold rolling) | Z1: Aluminum foil production (remelting & casting, hot rolling & cold rolling | AM1: Aluminum Can sheet rolling (Sphera 2021)
A2: Report unit | B2: 1000 kg aluminum sheet | N2: 1000 kg aluminum sheet | Z2: 1000 kg aluminum foil | AM2: input
A3: Scaling factor | B3: 1 | N3: 1 | Z3: 1 | AM3: Aluminum ingot for rolling | AN3: 1310 | AO3: kg
B4: Inputs | N4: Inputs | Z4: Parameter | AA4: Flows | AB4: Quantities | AC4: Amount | AD4: Factor | AE4: Units | AF4: Tracked flows | AG4: Standard deviation | AH4: Origin | AM4: Thermal energy from electricity | AN4: =1440 -> 1440 | AO4: MJ
B5: Parameter | C5: Flows | D5: Quantities | E5: Amount | F5: Factor | G5: Units | H5: Tracked flows | I5: Standard deviation | J5: Origin | N5: Parameter | O5: Flows | P5: Quantities | Q5: Amount | R5: Factor | S5: Units | T5: Tracked flows | U5: Standard deviation | V5: Origin | AA5: Alloying elements [Metals] | AB5: Mass | AC5: 10.300091 | AD5: 10.300091 | AE5: kg | AF5: X | AG5: 0 | AH5: (No statement) | AM5: Thermal energy from LPG | AN5: =0.155 -> 0.155 | AO5: MJ
C6: Alloying elements [Metals] | D6: Mass | E6: 9.5659601 | F6: 9.5659601 | G6: kg | H6: X | I6: 0 | J6: (No statement) | O6: Alloying elements [Metals] | P6: Mass | Q6: 6.8108895 | R6: 6.8108895 | S6: kg | T6: X | U6: 0 | V6: (No statement) | AA6: Argon [Inorganic intermediate products] | AB6: Mass | AC6: 1.5097313 | AD6: 1.5097313 | AE6: kg | AF6: X | AG6: 0 | AH6: (No statement) | AM6: Thermal energy from natural gas | AN6: 2910 | AO6: MJ
C7: Argon [Inorganic intermediate products] | D7: Mass | E7: 1.4021263 | F7: 1.4021263 | G7: kg | H7: X | I7: 0 | J7: (No statement) | O7: Argon [Inorganic intermediate products] | P7: Mass | Q7: 1.0659943 | R7: 1.0659943 | S7: kg | T7: X | U7: 0 | V7: (No statement) | AA7: Cardboard (packaging) [Materials from renewable raw materials] | AB7: Mass | AC7: 2.9867942 | AD7: 2.9867942 | AE7: kg | AF7: X | AG7: 0 | AH7: (No statement)
C8: Cardboard (packaging) [Materials from renewable raw materials] | D8: Mass | E8: 0.65319881 | F8: 0.65319881 | G8: kg | H8: X | I8: 0 | J8: (No statement) | O8: Cardboard (packaging) [Materials from renewable raw materials] | P8: Mass | Q8: 0.65659715 | R8: 0.65659715 | S8: kg | T8: X | U8: 0 | V8: (No statement) | AA8: Chlorine [Inorganic intermediate products] | AB8: Mass | AC8: 0.089505891 | AD8: 0.089505891 | AE8: kg | AF8: X | AG8: 0 | AH8: (No statement) | AM8: output
C9: Chlorine [Inorganic intermediate products] | D9: Mass | E9: 0.083126425 | F9: 0.083126425 | G9: kg | H9: X | I9: 0 | J9: (No statement) | O9: Chlorine [Inorganic intermediate products] | P9: Mass | Q9: 0.063198512 | R9: 0.063198512 | S9: kg | T9: X | U9: 0 | V9: (No statement) | AA9: Electricity [Electric power] | AB9: Energy (net calorific value) | AC9: 4813.6113 | AD9: 4813.6113 | AE9: MJ | AF9: X | AG9: 0 | AH9: (No statement) | AM9: Aluminum sheet for can production | AN9: =1000 -> 1000 | AO9: kg
C10: Electricity [Electric power] | D10: Energy (net calorific value) | E10: 3148.2446 | F10: 3148.2446 | G10: MJ | H10: X | I10: 0 | J10: (No statement) | O10: Electricity [Electric power] | P10: Energy (net calorific value) | Q10: 2970.8328 | R10: 2970.8328 | S10: MJ | T10: X | U10: 0 | V10: (No statement) | AA10: Filter media [Operating materials] | AB10: Mass | AC10: 0.44763711 | AD10: 0.44763711 | AE10: kg | AF10: X | AG10: 0 | AH10: (No statement) | AM10: Aluminum scrap for recovery | AN10: =308 -> 308 | AO10: kg
C11: Filter media [Operating materials] | D11: Mass | E11: 0.20670357 | F11: 0.20670357 | G11: kg | H11: X | I11: 0 | J11: (No statement) | O11: Filter media [Operating materials] | P11: Mass | Q11: 0.17471523 | R11: 0.17471523 | S11: kg | T11: X | U11: 0 | V11: (No statement) | AA11: Hydraulic oil [Operating materials] | AB11: Mass | AC11: 0.39837813 | AD11: 0.39837813 | AE11: kg | AF11: X | AG11: 0 | AH11: (No statement)
C12: Hydraulic oil [Operating materials] | D12: Mass | E12: 0.79886731 | F12: 0.79886731 | G12: kg | H12: X | I12: 0 | J12: (No statement) | O12: Hydraulic oil [Operating materials] | P12: Mass | Q12: 0.78701756 | R12: 0.78701756 | S12: kg | T12: X | U12: 0 | V12: (No statement) | AA12: Lime quicklime (lumpy) [Minerals] | AB12: Mass | AC12: 0.35178235 | AD12: 0.35178235 | AE12: kg | AF12: X | AG12: 0 | AH12: (No statement)
C13: Lime quicklime (lumpy) [Minerals] | D13: Mass | E13: 0.32670933 | F13: 0.32670933 | G13: kg | H13: X | I13: 0 | J13: (No statement) | O13: Lime quicklime (lumpy) [Minerals] | P13: Mass | Q13: 0.24838724 | R13: 0.24838724 | S13: kg | T13: X | U13: 0 | V13: (No statement) | AA13: Lubricant [Organic intermediate products] | AB13: Mass | AC13: 8.6940709 | AD13: 8.6940709 | AE13: kg | AF13: X | AG13: 0 | AH13: (No statement) | AM13: input | AN13: =AN3 -> 1310 | AO13: =20.9 -> 20.9 | AP13: kg
C14: Lubricant [Organic intermediate products] | D14: Mass | E14: 4.8061895 | F14: 4.8061895 | G14: kg | H14: X | I14: 0 | J14: (No statement) | O14: Lubricant [Organic intermediate products] | P14: Mass | Q14: 4.844189 | R14: 4.844189 | S14: kg | T14: X | U14: 0 | V14: (No statement) | AA14: Nitrogen gaseous [Inorganic intermediate products] | AB14: Mass | AC14: 231.96783 | AD14: 231.96783 | AE14: kg | AF14: X | AG14: 0 | AH14: (No statement) | AL14: Can sheet | AM14: output | AN14: =AN9 -> 1000 | AO14: =16 -> 16 | AP14: kg
C15: Nitrogen gaseous [Inorganic intermediate products] | D15: Mass | E15: 44.618358 | F15: 44.618358 | G15: kg | H15: X | I15: 0 | J15: (No statement) | O15: Nitrogen gaseous [Inorganic intermediate products] | P15: Mass | Q15: 38.222401 | R15: 38.222401 | S15: kg | T15: X | U15: 0 | V15: (No statement) | AA15: Packaging paper (not creditable) [Packaging] | AB15: Mass | AC15: 0.027833966 | AD15: 0.027833966 | AE15: kg | AF15: X | AG15: 0 | AH15: (No statement) | AM15: efficiency | AN15: =AN14/AN13 -> 0.76335878 | AO15: =AO14/AO13 -> 0.76555024
C16: Packaging paper (not creditable) [Packaging] | D16: Mass | E16: 0.14275217 | F16: 0.14275217 | G16: kg | H16: X | I16: 0 | J16: (No statement) | O16: Packaging paper (not creditable) [Packaging] | P16: Mass | Q16: 0.14291023 | R16: 0.14291023 | S16: kg | T16: X | U16: 0 | V16: (No statement) | AA16: Paint [Inorganic intermediate products] | AB16: Mass | AC16: 3.459991 | AD16: 3.459991 | AE16: kg | AF16: X | AG16: 0 | AH16: (No statement)
C17: Paint [Inorganic intermediate products] | D17: Mass | E17: 1.864156 | F17: 1.864156 | G17: kg | H17: X | I17: 0 | J17: (No statement) | O17: Paint [Inorganic intermediate products] | P17: Mass | Q17: 1.864156 | R17: 1.864156 | S17: kg | T17: X | U17: 0 | V17: (No statement) | AA17: Plastic packaging [Plastics] | AB17: Mass | AC17: 0.06861199 | AD17: 0.06861199 | AE17: kg | AF17: X | AG17: 0 | AH17: (No statement) | AM17: NG | AN17: =SUM(AN5:AN6) -> 2910.155 | AO17: MJ | AP17: =AN17/AN19 -> 0.66897731
C18: Plastic packaging [Plastics] | D18: Mass | E18: 0.2128239 | F18: 0.2128239 | G18: kg | H18: X | I18: 0 | J18: (No statement) | O18: Plastic packaging [Plastics] | P18: Mass | Q18: 0.21361422 | R18: 0.21361422 | S18: kg | T18: X | U18: 0 | V18: (No statement) | AA18: Potassium chloride [Inorganic intermediate products] | AB18: Mass | AC18: 0.75964839 | AD18: 0.75964839 | AE18: kg | AF18: X | AG18: 0 | AH18: (No statement) | AM18: Electricity | AN18: =AN4 -> 1440 | AO18: MJ | AP18: =AN18/AN19 -> 0.33102269
C19: Potassium chloride [Inorganic intermediate products] | D19: Mass | E19: 0.70550503 | F19: 0.70550503 | G19: kg | H19: X | I19: 0 | J19: (No statement) | O19: Potassium chloride [Inorganic intermediate products] | P19: Mass | Q19: 0.53637417 | R19: 0.53637417 | S19: kg | T19: X | U19: 0 | V19: (No statement) | AA19: Pre-treated comingled aluminum scrap [Metals] | AB19: Mass | AC19: 227.14866 | AD19: 227.14866 | AE19: kg | AF19: X | AG19: 0 | AH19: (No statement) | AM19: Energy | AN19: =SUM(AN17:AN18) -> 4350.155 | AO19: MJ
C20: Pre-treated comingled aluminum scrap [Metals] | D20: Mass | E20: 210.95881 | F20: 210.95881 | G20: kg | H20: X | I20: 0 | J20: (No statement) | O20: Pre-treated pre-consumer aluminum scrap [Metals] | P20: Mass | Q20: 254.97074 | R20: 254.97074 | S20: kg | T20: X | U20: 0 | V20: (No statement) | AA20: Pre-treated post-consumer aluminum scrap [Metals] | AB20: Mass | AC20: 206.64218 | AD20: 206.64218 | AE20: kg | AF20: X | AG20: 0 | AH20: (No statement)
C21: Pre-treated post-consumer aluminum scrap [Metals] | D21: Mass | E21: 191.91391 | F21: 191.91391 | G21: kg | H21: X | I21: 0 | J21: (No statement) | O21: Primary aluminum ingot [Valuable substances] | P21: Mass | Q21: 771.97271 | R21: 771.97271 | S21: kg | T21: X | U21: 0 | V21: (No statement) | AA21: Pre-treated pre-consumer aluminum scrap [Metals] | AB21: Mass | AC21: 600.99749 | AD21: 600.99749 | AE21: kg | AF21: X | AG21: 0 | AH21: (No statement) | AM21: MJ/kg-in | AN21: =AN19/AN13 -> 3.320729 | AO21: MJ/kg-ingot
A22: Valuable inputs and outputs | C22: Pre-treated pre-consumer aluminum scrap [Metals] | D22: Mass | E22: 558.16184 | F22: 558.16184 | G22: kg | H22: X | I22: 0 | J22: (No statement) | O22: Process and cooling water [Operating materials] | P22: Mass | Q22: 693.61665 | R22: 693.61665 | S22: kg | T22: X | U22: 0 | V22: (No statement) | AA22: Primary aluminum ingot [Valuable substances] | AB22: Mass | AC22: 278.57561 | AD22: 278.57561 | AE22: kg | AF22: X | AG22: 0 | AH22: (No statement) | AM22: MJ/kg-out | AN22: =AN19/AN14 -> 4.350155 | AO22: MJ/kg can sheet
A23: Energy consumption | C23: Primary aluminum ingot [Valuable substances] | D23: Mass | E23: 258.72035 | F23: 258.72035 | G23: kg | H23: X | I23: 0 | J23: (No statement) | O23: Refractory [Minerals] | P23: Mass | Q23: 0.52004842 | R23: 0.52004842 | S23: kg | T23: X | U23: 0 | V23: (No statement) | AA23: Process and cooling water [Operating materials] | AB23: Mass | AC23: 743.98752 | AD23: 743.98752 | AE23: kg | AF23: X | AG23: 0 | AH23: (No statement)
A24: Dross, scrap, etc. | C24: Process and cooling water [Operating materials] | D24: Mass | E24: 794.15068 | F24: 794.15068 | G24: kg | H24: X | I24: 0 | J24: (No statement) | O24: Rolling oil additive [Operating materials] | P24: Mass | Q24: 0.43882544 | R24: 0.43882544 | S24: kg | T24: X | U24: 0 | V24: (No statement) | AA24: Refractory [Minerals] | AB24: Mass | AC24: 0.73652679 | AD24: 0.73652679 | AE24: kg | AF24: X | AG24: 0 | AH24: (No statement) | AM24: Sweet/kg-in | AN24: =4.51/20.9 -> 0.21578947 | AO24: kg sweet/kg-ingot
C25: Refractory [Minerals] | D25: Mass | E25: 0.68403139 | F25: 0.68403139 | G25: kg | H25: X | I25: 0 | J25: (No statement) | O25: Sodium chloride (rock salt) [Inorganic intermediate products] | P25: Mass | Q25: 1.4835104 | R25: 1.4835104 | S25: kg | T25: X | U25: 0 | V25: (No statement) | AA25: Rolling oil additive [Operating materials] | AB25: Mass | AC25: 0.094349619 | AD25: 0.094349619 | AE25: kg | AF25: X | AG25: 0 | AH25: (No statement) | AM25: Sweet/kg-out | AN25: =4.51/16 -> 0.281875 | AO25: kg sweet/kg-sheet
C26: Rolling oil additive [Operating materials] | D26: Mass | E26: 0.43839037 | F26: 0.43839037 | G26: kg | H26: X | I26: 0 | J26: (No statement) | O26: Sodium hydroxide (100%; caustic soda) [Inorganic intermediate products] | P26: Mass | Q26: 0.037959608 | R26: 0.037959608 | S26: kg | T26: X | U26: 0 | V26: (No statement) | AA26: Secondary aluminum ingot [Valuable substances] | AB26: Mass | AC26: 57.891359 | AD26: 57.891359 | AE26: kg | AF26: X | AG26: 0 | AH26: (No statement)
C27: Secondary aluminum ingot [Valuable substances] | D27: Mass | E27: 53.765196 | F27: 53.765196 | G27: kg | H27: X | I27: 0 | J27: (No statement) | O27: Solvent [Operating materials] | P27: Mass | Q27: 0.030257618 | R27: 0.030257618 | S27: kg | T27: X | U27: 0 | V27: (No statement) | AA27: Sodium chloride (rock salt) [Inorganic intermediate products] | AB27: Mass | AC27: 2.1010451 | AD27: 2.1010451 | AE27: kg | AF27: X | AG27: 0 | AH27: (No statement) | AM27: kg CO2e/kg-can | AN27: =7.19/12.99 -> 0.55350269
C28: Sodium chloride (rock salt) [Inorganic intermediate products] | D28: Mass | E28: 1.9512946 | F28: 1.9512946 | G28: kg | H28: X | I28: 0 | J28: (No statement) | O28: Steel band (packaging) [Metals] | P28: Mass | Q28: 0.29821317 | R28: 0.29821317 | S28: kg | T28: X | U28: 0 | V28: (No statement) | AA28: Sodium hydroxide (100%; caustic soda) [Inorganic intermediate products] | AB28: Mass | AC28: 0.053760894 | AD28: 0.053760894 | AE28: kg | AF28: X | AG28: 0 | AH28: (No statement) | AM28: kg CO2e/kg-sheet | AN28: =AN27*AN44 -> 0.4670179
C29: Sodium hydroxide (100%; caustic soda) [Inorganic intermediate products] | D29: Mass | E29: 0.049929127 | F29: 0.049929127 | G29: kg | H29: X | I29: 0 | J29: (No statement) | O29: Sulphuric acid (100%) [Inorganic intermediate products] | P29: Mass | Q29: 0.58524847 | R29: 0.58524847 | S29: kg | T29: X | U29: 0 | V29: (No statement) | AA29: Solvent [Operating materials] | AB29: Mass | AC29: 0.042852829 | AD29: 0.042852829 | AE29: kg | AF29: X | AG29: 0 | AH29: (No statement) | AM29: kg CO2e/kg-ingot | AN29: =AN28*AN15 -> 0.35650221
C30: Solvent [Operating materials] | D30: Mass | E30: 0.039798526 | F30: 0.039798526 | G30: kg | H30: X | I30: 0 | J30: (No statement) | O30: Thermal energy from diesel fuel (MJ) [Thermal energy] | P30: Energy (net calorific value) | Q30: 9.0670097 | R30: 9.0670097 | S30: MJ | T30: X | U30: 0 | V30: (No statement) | AA30: Steel band (packaging) [Metals] | AB30: Mass | AC30: 0.61912354 | AD30: 0.61912354 | AE30: kg | AF30: X | AG30: 0 | AH30: (No statement)
C31: Steel band (packaging) [Metals] | D31: Mass | E31: 0.30078027 | F31: 0.30078027 | G31: kg | H31: X | I31: 0 | J31: (No statement) | O31: Thermal energy from heavy fuel oil (MJ) [Thermal energy] | P31: Energy (net calorific value) | Q31: 0.109785 | R31: 0.109785 | S31: MJ | T31: X | U31: 0 | V31: (No statement) | AA31: Sulphuric acid (100%) [Inorganic intermediate products] | AB31: Mass | AC31: 0.82886739 | AD31: 0.82886739 | AE31: kg | AF31: X | AG31: 0 | AH31: (No statement) | AM31: Aluminum Can Mfg. (Sphera 2021)
C32: Sulphuric acid (100%) [Inorganic intermediate products] | D32: Mass | E32: 0.76979049 | F32: 0.76979049 | G32: kg | H32: X | I32: 0 | J32: (No statement) | O32: Thermal energy from LPG (MJ) [Thermal energy] | P32: Energy (net calorific value) | Q32: 3.6477097 | R32: 3.6477097 | S32: MJ | T32: X | U32: 0 | V32: (No statement) | AA32: Thermal energy from diesel fuel (MJ) [Thermal energy] | AB32: Energy (net calorific value) | AC32: 4.7320568 | AD32: 4.7320568 | AE32: MJ | AF32: X | AG32: 0 | AH32: (No statement) | AM32: input
C33: Thermal energy from diesel fuel (MJ) [Thermal energy] | D33: Energy (net calorific value) | E33: 9.5117205 | F33: 9.5117205 | G33: MJ | H33: X | I33: 0 | J33: (No statement) | O33: Thermal energy from natural gas (MJ) [Thermal energy] | P33: Energy (net calorific value) | Q33: 8146.4733 | R33: 8146.4733 | S33: MJ | T33: X | U33: 0 | V33: (No statement) | AA33: Thermal energy from LPG (MJ) [Thermal energy] | AB33: Energy (net calorific value) | AC33: 5.1661265 | AD33: 5.1661265 | AE33: MJ | AF33: X | AG33: 0 | AH33: (No statement) | AM33: Aluminum sheet | AN33: 16 | AO33: kg
C34: Thermal energy from heavy fuel oil (MJ) [Thermal energy] | D34: Energy (net calorific value) | E34: 0.109785 | F34: 0.109785 | G34: MJ | H34: X | I34: 0 | J34: (No statement) | O34: Thermal energy from propane (MJ) [Thermal energy] | P34: Energy (net calorific value) | Q34: 9.1958776 | R34: 9.1958776 | S34: MJ | T34: X | U34: 0 | V34: (No statement) | AA34: Thermal energy from natural gas (MJ) [Thermal energy] | AB34: Energy (net calorific value) | AC34: 12026.827 | AD34: 12026.827 | AE34: MJ | AF34: X | AG34: 0 | AH34: (No statement) | AM34: Electricity | AN34: 109 | AO34: MJ
C35: Thermal energy from LPG (MJ) [Thermal energy] | D35: Energy (net calorific value) | E35: 4.7979147 | F35: 4.7979147 | G35: MJ | H35: X | I35: 0 | J35: (No statement) | O35: Thermal energy from waste (MJ) [Thermal energy] | P35: Energy (net calorific value) | Q35: 6.2770412 | R35: 6.2770412 | S35: MJ | T35: X | U35: 0 | V35: (No statement) | AA35: Thermal energy from propane (MJ) [Thermal energy] | AB35: Energy (net calorific value) | AC35: 22.37329 | AD35: 22.37329 | AE35: MJ | AF35: X | AG35: 0 | AH35: (No statement) | AM35: Thermal energy from natural gas | AN35: 67.5 | AO35: MJ
C36: Thermal energy from natural gas (MJ) [Thermal energy] | D36: Energy (net calorific value) | E36: 9632.7005 | F36: 9632.7005 | G36: MJ | H36: X | I36: 0 | J36: (No statement) | O36: Wood packaging [Materials from renewable raw materials] | P36: Mass | Q36: 4.1194338 | R36: 4.1194338 | S36: kg | T36: X | U36: 0 | V36: (No statement) | AA36: Thermal energy from waste (MJ) [Thermal energy] | AB36: Energy (net calorific value) | AC36: 8.8899588 | AD36: 8.8899588 | AE36: MJ | AF36: X | AG36: 0 | AH36: (No statement)
